Workbook

Sheet Jan '25
E1: JAIKALKI TECHNOLOGY PVT. LTD.
E2: Employee Attendance Sheet
B3: =HLOOKUP(B6,$E$3:$O$4,2,0) -> 1 | E3: January | F3: February | G3: March | H3: April | I3: May | J3: June | K3: July | L3: August | M3: September | N3: October | O3: Novemeber | P3: December
E4: 1 | F4: 2 | G4: 3 | H4: 4 | I4: 5 | J4: 6 | K4: 7 | L4: 8 | M4: 9 | N4: 10 | O4: 11 | P4: 12
A5: Year | B5: 2025 | C5: D O B | D5: D O J | E5: Date | F5: 1 | G5: 2 | H5: 3 | I5: 4 | J5: 5 | K5: 6 | L5: 7 | M5: 8 | N5: 9 | O5: 10 | P5: 11 | Q5: 12 | R5: 13 | S5: 14 | T5: 15 | U5: 16 | V5: 17 | W5: 18 | X5: 19 | Y5: 20 | Z5: 21 | AA5: 22 | AB5: 23 | AC5: 24 | AD5: 25 | AE5: 26 | AF5: 27 | AG5: 28 | AH5: 29 | AI5: 30 | AJ5: 31 | AK5: Monthly Attendance Summary
A6: Month | B6: January | E6: Type of Day | F6: =IF(F7="Sun","H","W") -> W | G6: =IF(G7="Sun","H","W") -> W | H6: =IF(H7="Sun","H","W") -> W | I6: =IF(I7="Sun","H","W") -> W | J6: =IF(J7="Sun","H","W") -> H | K6: =IF(K7="Sun","H","W") -> W | L6: =IF(L7="Sun","H","W") -> W | M6: =IF(M7="Sun","H","W") -> W | ... AJ6: =IF(AJ7="Sun","H","W") -> W
A7: Emp. ID | B7: Employee Name | E7: Month | F7: =IFERROR(TEXT(DATE($B$5,$B$3,F$5),"ddd"),"") -> Wed | G7: =IFERROR(TEXT(DATE($B$5,$B$3,G$5),"ddd"),"") -> Thu | H7: =IFERROR(TEXT(DATE($B$5,$B$3,H$5),"ddd"),"") -> Fri | I7: =IFERROR(TEXT(DATE($B$5,$B$3,I$5),"ddd"),"") -> Sat | J7: =IFERROR(TEXT(DATE($B$5,$B$3,J$5),"ddd"),"") -> Sun | K7: =IFERROR(TEXT(DATE($B$5,$B$3,K$5),"ddd"),"") -> Mon | L7: =IFERROR(TEXT(DATE($B$5,$B$3,L$5),"ddd"),"") -> Tue | M7: =IFERROR(TEXT(DATE($B$5,$B$3,M$5),"ddd"),"") -> Wed | ... AJ7: =IFERROR(TEXT(DATE($B$5,$B$3,AJ$5),"ddd"),"") -> Fri | AK7: P | AL7: L | AM7: HD | AN7: NH | AO7: FH | AP7: T | AQ7: ML | AR7: EL | AS7: EL AL | AT7: SL | AU7: SL AL | AV7: CL | AW7: CL AL | AX7: Working Days | AY7: Days Payable
A8: JKT001 | B8: Shyamveer Singh | C8: 11th Sept 1991 | D8: 14th Sept 2024 | E8: =$B$6 -> January | Y8: P | Z8: P | AA8: P | AB8: P | AC8: P | AD8: P | AE8: P | AF8: P | AG8: P | AH8: P | AI8: P | AJ8: P | AK8: =COUNTIF(F8:AJ8,"P") -> 12 | AL8: =COUNTIF(F8:AJ8,"L") -> 0 | AM8: =COUNTIF(F8:AJ8,"HD") -> 0 | AN8: =COUNTIF(F8:AJ8,"NH") -> 0 | AO8: =COUNTIF(F8:AJ8,"FH") -> 0 | AP8: =COUNTIF(F8:AJ8,"T") -> 0 | AQ8: =COUNTIF(F8:AJ8,"ML") -> 0 | AR8: =COUNTIF(F8:AJ8,"EL") -> 0 | AS8: 1 | AT8: =COUNTIF(O8:AS8,"SL") -> 0 | AU8: 2 | AV8: =COUNTIF(F8:AJ8,"CL") -> 0 | AW8: 2 | AX8: =AK8+AL8+(AM8+AN8+AO8+AP8+AQ8+AR8+AT8+AV8) -> 12 | AY8: =AX8-AL8-(AM8/2) -> 12
A9: JKT002 | B9: Rohitkumar Kannojiya | C9: 10th May 2001 | D9: 14th Sept 2024 | E9: =$B$6 -> January | Y9: P | Z9: P | AA9: P | AB9: P | AC9: P | AD9: P | AE9: P | AF9: P | AG9: P | AH9: P | AI9: P | AJ9: P | AK9: =COUNTIF(F9:AJ9,"P") -> 12 | AL9: =COUNTIF(F9:AJ9,"L") -> 0 | AM9: =COUNTIF(F9:AJ9,"HD") -> 0 | AN9: =COUNTIF(F9:AJ9,"NH") -> 0 | AO9: =COUNTIF(F9:AJ9,"FH") -> 0 | AP9: =COUNTIF(F9:AJ9,"T") -> 0 | AQ9: =COUNTIF(F9:AJ9,"ML") -> 0 | AR9: =COUNTIF(F9:AJ9,"EL") -> 0 | AS9: 1 | AT9: =COUNTIF(O9:AS9,"SL") -> 0 | AU9: 2 | AV9: =COUNTIF(F9:AJ9,"CL") -> 0 | AW9: 2 | AX9: =AK9+AL9+(AM9+AN9+AO9+AP9+AQ9+AR9+AT9+AV9) -> 12 | AY9: =AX9-AL9-(AM9/2) -> 12
A10: JKT003 | B10: Krunal Trivedi | C10: 29th May 1987 | D10: 14th Sept 2024 | E10: =$B$6 -> January | Y10: P | Z10: P | AA10: P | AB10: P | AC10: P | AD10: P | AE10: P | AF10: P | AG10: P | AH10: P | AI10: P | AJ10: P | AK10: =COUNTIF(F10:AJ10,"P") -> 12 | AL10: =COUNTIF(F10:AJ10,"L") -> 0 | AM10: =COUNTIF(F10:AJ10,"HD") -> 0 | AN10: =COUNTIF(F10:AJ10,"NH") -> 0 | AO10: =COUNTIF(F10:AJ10,"FH") -> 0 | AP10: =COUNTIF(F10:AJ10,"T") -> 0 | AQ10: =COUNTIF(F10:AJ10,"ML") -> 0 | AR10: =COUNTIF(F10:AJ10,"EL") -> 0 | AS10: 1 | AT10: =COUNTIF(O10:AS10,"SL") -> 0 | AU10: 2 | AV10: =COUNTIF(F10:AJ10,"CL") -> 0 | AW10: 2 | AX10: =AK10+AL10+(AM10+AN10+AO10+AP10+AQ10+AR10+AT10+AV10) -> 12 | AY10: =AX10-AL10-(AM10/2) -> 12
A11: JKT004 | B11: Ranjeetkumar Yadav | C11: 27th Mar 1987 | D11: 14th Sept 2024 | E11: =$B$6 -> January | Y11: P | Z11: P | AA11: P | AB11: P | AC11: P | AD11: P | AE11: P | AF11: P | AG11: P | AH11: P | AI11: P | AJ11: P | AK11: =COUNTIF(F11:AJ11,"P") -> 12 | AL11: =COUNTIF(F11:AJ11,"L") -> 0 | AM11: =COUNTIF(F11:AJ11,"HD") -> 0 | AN11: =COUNTIF(F11:AJ11,"NH") -> 0 | AO11: =COUNTIF(F11:AJ11,"FH") -> 0 | AP11: =COUNTIF(F11:AJ11,"T") -> 0 | AQ11: =COUNTIF(F11:AJ11,"ML") -> 0 | AR11: =COUNTIF(F11:AJ11,"EL") -> 0 | AS11: 1 | AT11: =COUNTIF(O11:AS11,"SL") -> 0 | AU11: 2 | AV11: =COUNTIF(F11:AJ11,"CL") -> 0 | AW11: 2 | AX11: =AK11+AL11+(AM11+AN11+AO11+AP11+AQ11+AR11+AT11+AV11) -> 12 | AY11: =AX11-AL11-(AM11/2) -> 12
A12: JKT005 | B12: Santosh Vishwakarma | C12: 4th Jul 1998 | D12: 14th Sept 2024 | E12: =$B$6 -> January | Y12: P | Z12: P | AA12: P | AB12: P | AC12: P | AD12: P | AE12: P | AF12: P | AG12: P | AH12: P | AI12: P | AJ12: P | AK12: =COUNTIF(F12:AJ12,"P") -> 12 | AL12: =COUNTIF(F12:AJ12,"L") -> 0 | AM12: =COUNTIF(F12:AJ12,"HD") -> 0 | AN12: =COUNTIF(F12:AJ12,"NH") -> 0 | AO12: =COUNTIF(F12:AJ12,"FH") -> 0 | AP12: =COUNTIF(F12:AJ12,"T") -> 0 | AQ12: =COUNTIF(F12:AJ12,"ML") -> 0 | AR12: =COUNTIF(F12:AJ12,"EL") -> 0 | AS12: 1 | AT12: =COUNTIF(O12:AS12,"SL") -> 0 | AU12: 2 | AV12: =COUNTIF(F12:AJ12,"CL") -> 0 | AW12: 2 | AX12: =AK12+AL12+(AM12+AN12+AO12+AP12+AQ12+AR12+AT12+AV12) -> 12 | AY12: =AX12-AL12-(AM12/2) -> 12
A13: JKT006 | B13: Deepak Borana | C13: 23rd June 2000 | D13: 6th Jan 2025 | E13: =$B$6 -> January | Y13: P | Z13: P | AA13: P | AB13: P | AC13: P | AD13: P | AE13: P | AF13: P | AG13: P | AH13: P | AI13: P | AJ13: P | AK13: =COUNTIF(F13:AJ13,"P") -> 12 | AL13: =COUNTIF(F13:AJ13,"L") -> 0 | AM13: =COUNTIF(F13:AJ13,"HD") -> 0 | AN13: =COUNTIF(F13:AJ13,"NH") -> 0 | AO13: =COUNTIF(F13:AJ13,"FH") -> 0 | AP13: =COUNTIF(F13:AJ13,"T") -> 0 | AQ13: =COUNTIF(F13:AJ13,"ML") -> 0 | AR13: =COUNTIF(F13:AJ13,"EL") -> 0 | AS13: 1 | AT13: =COUNTIF(F13:AJ13,"SL") -> 0 | AU13: 2 | AV13: =COUNTIF(F13:AJ13,"CL") -> 0 | AW13: 2 | AX13: =AK13+AL13+(AM13+AN13+AO13+AP13+AQ13+AR13+AT13+AV13) -> 12 | AY13: =AX13-AL13-(AM13/2) -> 12
A14: JKT007 | B14: Jincy Mathew | C14: 19th April 1999 | D14: 13th Jan 2025 | E14: =$B$6 -> January | Y14: P | Z14: P | AA14: P | AB14: P | AC14: P | AD14: L | AE14: P | AF14: P | AG14: P | AH14: P | AI14: P | AJ14: P | AK14: =COUNTIF(F14:AJ14,"P") -> 11 | AL14: =COUNTIF(F14:AJ14,"L") -> 1 | AM14: =COUNTIF(F14:AJ14,"HD") -> 0 | AN14: =COUNTIF(F14:AJ14,"NH") -> 0 | AO14: =COUNTIF(F14:AJ14,"FH") -> 0 | AP14: =COUNTIF(F14:AJ14,"T") -> 0 | AQ14: =COUNTIF(F14:AJ14,"ML") -> 0 | AR14: =COUNTIF(F14:AJ14,"EL") -> 0 | AS14: 1 | AT14: =COUNTIF(F14:AJ14,"SL") -> 0 | AU14: 2 | AV14: =COUNTIF(F14:AJ14,"CL") -> 0 | AW14: 2 | AX14: =AK14+AL14+(AM14+AN14+AO14+AP14+AQ14+AR14+AT14+AV14) -> 12 | AY14: =AX14-AL14-(AM14/2) -> 11
A15: JKT008 | B15: Sanjay Jaiswar | C15: 18th Feb 2002 | D15: 16th Jan 2025 | E15: =$B$6 -> January | Y15: P | Z15: P | AA15: P | AB15: P | AC15: P | AD15: P | AE15: P | AF15: P | AG15: P | AH15: P | AI15: P | AJ15: P | AK15: =COUNTIF(F15:AJ15,"P") -> 12 | AL15: =COUNTIF(F15:AJ15,"L") -> 0 | AM15: =COUNTIF(F15:AJ15,"HD") -> 0 | AN15: =COUNTIF(F15:AJ15,"NH") -> 0 | AO15: =COUNTIF(F15:AJ15,"FH") -> 0 | AP15: =COUNTIF(F15:AJ15,"T") -> 0 | AQ15: =COUNTIF(F15:AJ15,"ML") -> 0 | AR15: =COUNTIF(F15:AJ15,"EL") -> 0 | AS15: 1 | AT15: =COUNTIF(F15:AJ15,"SL") -> 0 | AU15: 2 | AV15: =COUNTIF(F15:AJ15,"CL") -> 0 | AW15: 2 | AX15: =AK15+AL15+(AM15+AN15+AO15+AP15+AQ15+AR15+AT15+AV15) -> 12 | AY15: =AX15-AL15-(AM15/2) -> 12
A16: JKT009 | B16: Chauhan Badal | C16: 12th Mar 2002 | D16: 30th Jan 2025 | E16: =$B$6 -> January | Y16: P | Z16: P | AA16: P | AB16: P | AC16: P | AD16: L | AE16: P | AF16: P | AG16: P | AH16: P | AI16: P | AJ16: P | AK16: =COUNTIF(F16:AJ16,"P") -> 11 | AL16: =COUNTIF(F16:AJ16,"L") -> 1 | AM16: =COUNTIF(F16:AJ16,"HD") -> 0 | AN16: =COUNTIF(F16:AJ16,"NH") -> 0 | AO16: =COUNTIF(F16:AJ16,"FH") -> 0 | AP16: =COUNTIF(F16:AJ16,"T") -> 0 | AQ16: =COUNTIF(F16:AJ16,"ML") -> 0 | AR16: =COUNTIF(F16:AJ16,"EL") -> 0 | AS16: 1 | AT16: =COUNTIF(F16:AJ16,"SL") -> 0 | AU16: 2 | AV16: =COUNTIF(F16:AJ16,"CL") -> 0 | AW16: 2 | AX16: =AK16+AL16+(AM16+AN16+AO16+AP16+AQ16+AR16+AT16+AV16) -> 12 | AY16: =AX16-AL16-(AM16/2) -> 11
A17: JKT010 | B17: Vikas Kotiyan | C17: 18th Sept 1999 | D17: 17th Mar 2025 | E17: =$B$6 -> January | Y17: P | Z17: P | AA17: P | AB17: P | AC17: P | AD17: P | AE17: P | AF17: P | AG17: P | AH17: P | AI17: P | AJ17: P | AK17: =COUNTIF(F17:AJ17,"P") -> 12 | AL17: =COUNTIF(F17:AJ17,"L") -> 0 | AM17: =COUNTIF(F17:AJ17,"HD") -> 0 | AN17: =COUNTIF(F17:AJ17,"NH") -> 0 | AO17: =COUNTIF(F17:AJ17,"FH") -> 0 | AP17: =COUNTIF(F17:AJ17,"T") -> 0 | AQ17: =COUNTIF(F17:AJ17,"ML") -> 0 | AR17: =COUNTIF(F17:AJ17,"EL") -> 0 | AS17: 1 | AT17: =COUNTIF(F17:AJ17,"SL") -> 0 | AU17: 2 | AV17: =COUNTIF(F17:AJ17,"CL") -> 0 | AW17: 2 | AX17: =AK17+AL17+(AM17+AN17+AO17+AP17+AQ17+AR17+AT17+AV17) -> 12 | AY17: =AX17-AL17-(AM17/2) -> 12
A18: JKT011 | B18: Pratibha Tiwari | C18: 14th Feb 2004 | D18: 17th Apr 2025 | E18: =$B$6 -> January | Y18: P | Z18: P | AA18: P | AB18: P | AC18: P | AD18: P | AE18: P | AF18: P | AG18: P | AH18: P | AI18: P | AJ18: P | AK18: =COUNTIF(F18:AJ18,"P") -> 12 | AL18: =COUNTIF(F18:AJ18,"L") -> 0 | AM18: =COUNTIF(F18:AJ18,"HD") -> 0 | AN18: =COUNTIF(F18:AJ18,"NH") -> 0 | AO18: =COUNTIF(F18:AJ18,"FH") -> 0 | AP18: =COUNTIF(F18:AJ18,"T") -> 0 | AQ18: =COUNTIF(F18:AJ18,"ML") -> 0 | AR18: =COUNTIF(F18:AJ18,"EL") -> 0 | AS18: 1 | AT18: =COUNTIF(F18:AJ18,"SL") -> 0 | AU18: 2 | AV18: =COUNTIF(F18:AJ18,"CL") -> 0 | AW18: 2 | AX18: =AK18+AL18+(AM18+AN18+AO18+AP18+AQ18+AR18+AT18+AV18) -> 12 | AY18: =AX18-AL18-(AM18/2) -> 12
AK19: =COUNTIF(F19:AJ19,"P") -> 0 | AL19: =COUNTIF(F19:AJ19,"L") -> 0 | AM19: =COUNTIF(F19:AJ19,"HD") -> 0 | AN19: =COUNTIF(F19:AJ19,"NH") -> 0 | AO19: =COUNTIF(F19:AJ19,"FH") -> 0 | AP19: =COUNTIF(F19:AJ19,"T") -> 0 | AQ19: =COUNTIF(F19:AJ19,"ML") -> 0 | AR19: =COUNTIF(F19:AJ19,"EL") -> 0 | AS19: 1 | AT19: =COUNTIF(F19:AJ19,"SL") -> 0 | AU19: 2 | AV19: =COUNTIF(F19:AJ19,"CL") -> 0 | AW19: 2 | AX19: =AK19+AL19+(AM19+AN19+AO19+AP19+AQ19+AR19+AT19+AV19) -> 0 | AY19: =AX19-AL19-(AM19/2) -> 0
AK20: =COUNTIF(F20:AJ20,"P") -> 0 | AL20: =COUNTIF(F20:AJ20,"L") -> 0 | AM20: =COUNTIF(F20:AJ20,"HD") -> 0 | AN20: =COUNTIF(F20:AJ20,"NH") -> 0 | AO20: =COUNTIF(F20:AJ20,"FH") -> 0 | AP20: =COUNTIF(F20:AJ20,"T") -> 0 | AQ20: =COUNTIF(F20:AJ20,"ML") -> 0 | AR20: =COUNTIF(F20:AJ20,"EL") -> 0 | AS20: 1 | AT20: =COUNTIF(F20:AJ20,"SL") -> 0 | AU20: 2 | AV20: =COUNTIF(F20:AJ20,"CL") -> 0 | AW20: 2 | AX20: =AK20+AL20+(AM20+AN20+AO20+AP20+AQ20+AR20+AT20+AV20) -> 0 | AY20: =AX20-AL20-(AM20/2) -> 0
AK21: =COUNTIF(F21:AJ21,"P") -> 0 | AL21: =COUNTIF(F21:AJ21,"L") -> 0 | AM21: =COUNTIF(F21:AJ21,"HD") -> 0 | AN21: =COUNTIF(F21:AJ21,"NH") -> 0 | AO21: =COUNTIF(F21:AJ21,"FH") -> 0 | AP21: =COUNTIF(F21:AJ21,"T") -> 0 | AQ21: =COUNTIF(F21:AJ21,"ML") -> 0 | AR21: =COUNTIF(F21:AJ21,"EL") -> 0 | AS21: 1 | AT21: =COUNTIF(F21:AJ21,"SL") -> 0 | AU21: 2 | AV21: =COUNTIF(F21:AJ21,"CL") -> 0 | AW21: 2 | AX21: =AK21+AL21+(AM21+AN21+AO21+AP21+AQ21+AR21+AT21+AV21) -> 0 | AY21: =AX21-AL21-(AM21/2) -> 0
AK22: =COUNTIF(F22:AJ22,"P") -> 0 | AL22: =COUNTIF(F22:AJ22,"L") -> 0 | AM22: =COUNTIF(F22:AJ22,"HD") -> 0 | AN22: =COUNTIF(F22:AJ22,"NH") -> 0 | AO22: =COUNTIF(F22:AJ22,"FH") -> 0 | AP22: =COUNTIF(F22:AJ22,"T") -> 0 | AQ22: =COUNTIF(F22:AJ22,"ML") -> 0 | AR22: =COUNTIF(F22:AJ22,"EL") -> 0 | AS22: 1 | AT22: =COUNTIF(F22:AJ22,"SL") -> 0 | AU22: 2 | AV22: =COUNTIF(F22:AJ22,"CL") -> 0 | AW22: 2 | AX22: =AK22+AL22+(AM22+AN22+AO22+AP22+AQ22+AR22+AT22+AV22) -> 0 | AY22: =AX22-AL22-(AM22/2) -> 0
AK23: =COUNTIF(F23:AJ23,"P") -> 0 | AL23: =COUNTIF(F23:AJ23,"L") -> 0 | AM23: =COUNTIF(F23:AJ23,"HD") -> 0 | AN23: =COUNTIF(F23:AJ23,"NH") -> 0 | AO23: =COUNTIF(F23:AJ23,"FH") -> 0 | AP23: =COUNTIF(F23:AJ23,"T") -> 0 | AQ23: =COUNTIF(F23:AJ23,"ML") -> 0 | AR23: =COUNTIF(F23:AJ23,"EL") -> 0 | AS23: 1 | AT23: =COUNTIF(F23:AJ23,"SL") -> 0 | AU23: 2 | AV23: =COUNTIF(F23:AJ23,"CL") -> 0 | AW23: 2 | AX23: =AK23+AL23+(AM23+AN23+AO23+AP23+AQ23+AR23+AT23+AV23) -> 0 | AY23: =AX23-AL23-(AM23/2) -> 0
AK24: =COUNTIF(F24:AJ24,"P") -> 0 | AL24: =COUNTIF(F24:AJ24,"L") -> 0 | AM24: =COUNTIF(F24:AJ24,"HD") -> 0 | AN24: =COUNTIF(F24:AJ24,"NH") -> 0 | AO24: =COUNTIF(F24:AJ24,"FH") -> 0 | AP24: =COUNTIF(F24:AJ24,"T") -> 0 | AQ24: =COUNTIF(F24:AJ24,"ML") -> 0 | AR24: =COUNTIF(F24:AJ24,"EL") -> 0 | AS24: 1 | AT24: =COUNTIF(F24:AJ24,"SL") -> 0 | AU24: 2 | AV24: =COUNTIF(F24:AJ24,"CL") -> 0 | AW24: 2 | AX24: =AK24+AL24+(AM24+AN24+AO24+AP24+AQ24+AR24+AT24+AV24) -> 0 | AY24: =AX24-AL24-(AM24/2) -> 0
AK25: =COUNTIF(F25:AJ25,"P") -> 0 | AL25: =COUNTIF(F25:AJ25,"L") -> 0 | AM25: =COUNTIF(F25:AJ25,"HD") -> 0 | AN25: =COUNTIF(F25:AJ25,"NH") -> 0 | AO25: =COUNTIF(F25:AJ25,"FH") -> 0 | AP25: =COUNTIF(F25:AJ25,"T") -> 0 | AQ25: =COUNTIF(F25:AJ25,"ML") -> 0 | AR25: =COUNTIF(F25:AJ25,"EL") -> 0 | AS25: 1 | AT25: =COUNTIF(F25:AJ25,"SL") -> 0 | AU25: 2 | AV25: =COUNTIF(F25:AJ25,"CL") -> 0 | AW25: 2 | AX25: =AK25+AL25+(AM25+AN25+AO25+AP25+AQ25+AR25+AT25+AV25) -> 0 | AY25: =AX25-AL25-(AM25/2) -> 0
AK26: =COUNTIF(F26:AJ26,"P") -> 0 | AL26: =COUNTIF(F26:AJ26,"L") -> 0 | AM26: =COUNTIF(F26:AJ26,"HD") -> 0 | AN26: =COUNTIF(F26:AJ26,"NH") -> 0 | AO26: =COUNTIF(F26:AJ26,"FH") -> 0 | AP26: =COUNTIF(F26:AJ26,"T") -> 0 | AQ26: =COUNTIF(F26:AJ26,"ML") -> 0 | AR26: =COUNTIF(F26:AJ26,"EL") -> 0 | AS26: 1 | AT26: =COUNTIF(F26:AJ26,"SL") -> 0 | AU26: 2 | AV26: =COUNTIF(F26:AJ26,"CL") -> 0 | AW26: 2 | AX26: =AK26+AL26+(AM26+AN26+AO26+AP26+AQ26+AR26+AT26+AV26) -> 0 | AY26: =AX26-AL26-(AM26/2) -> 0
AK27: =COUNTIF(F27:AJ27,"P") -> 0 | AL27: =COUNTIF(F27:AJ27,"L") -> 0 | AM27: =COUNTIF(F27:AJ27,"HD") -> 0 | AN27: =COUNTIF(F27:AJ27,"NH") -> 0 | AO27: =COUNTIF(F27:AJ27,"FH") -> 0 | AP27: =COUNTIF(F27:AJ27,"T") -> 0 | AQ27: =COUNTIF(F27:AJ27,"ML") -> 0 | AR27: =COUNTIF(F27:AJ27,"EL") -> 0 | AS27: 1 | AT27: =COUNTIF(F27:AJ27,"SL") -> 0 | AU27: 2 | AV27: =COUNTIF(F27:AJ27,"CL") -> 0 | AW27: 2 | AX27: =AK27+AL27+(AM27+AN27+AO27+AP27+AQ27+AR27+AT27+AV27) -> 0 | AY27: =AX27-AL27-(AM27/2) -> 0
AK28: =COUNTIF(F28:AJ28,"P") -> 0 | AL28: =COUNTIF(F28:AJ28,"L") -> 0 | AM28: =COUNTIF(F28:AJ28,"HD") -> 0 | AN28: =COUNTIF(F28:AJ28,"NH") -> 0 | AO28: =COUNTIF(F28:AJ28,"FH") -> 0 | AP28: =COUNTIF(F28:AJ28,"T") -> 0 | AQ28: =COUNTIF(F28:AJ28,"ML") -> 0 | AR28: =COUNTIF(F28:AJ28,"EL") -> 0 | AS28: 1 | AT28: =COUNTIF(F28:AJ28,"SL") -> 0 | AU28: 2 | AV28: =COUNTIF(F28:AJ28,"CL") -> 0 | AW28: 2 | AX28: =AK28+AL28+(AM28+AN28+AO28+AP28+AQ28+AR28+AT28+AV28) -> 0 | AY28: =AX28-AL28-(AM28/2) -> 0
AK29: =COUNTIF(F29:AJ29,"P") -> 0 | AL29: =COUNTIF(F29:AJ29,"L") -> 0 | AM29: =COUNTIF(F29:AJ29,"HD") -> 0 | AN29: =COUNTIF(F29:AJ29,"NH") -> 0 | AO29: =COUNTIF(F29:AJ29,"FH") -> 0 | AP29: =COUNTIF(F29:AJ29,"T") -> 0 | AQ29: =COUNTIF(F29:AJ29,"ML") -> 0 | AR29: =COUNTIF(F29:AJ29,"EL") -> 0 | AS29: 1 | AT29: =COUNTIF(F29:AJ29,"SL") -> 0 | AU29: 2 | AV29: =COUNTIF(F29:AJ29,"CL") -> 0 | AW29: 2 | AX29: =AK29+AL29+(AM29+AN29+AO29+AP29+AQ29+AR29+AT29+AV29) -> 0 | AY29: =AX29-AL29-(AM29/2) -> 0
AK30: =COUNTIF(F30:AJ30,"P") -> 0 | AL30: =COUNTIF(F30:AJ30,"L") -> 0 | AM30: =COUNTIF(F30:AJ30,"HD") -> 0 | AN30: =COUNTIF(F30:AJ30,"NH") -> 0 | AO30: =COUNTIF(F30:AJ30,"FH") -> 0 | AP30: =COUNTIF(F30:AJ30,"T") -> 0 | AQ30: =COUNTIF(F30:AJ30,"ML") -> 0 | AR30: =COUNTIF(F30:AJ30,"EL") -> 0 | AS30: 1 | AT30: =COUNTIF(F30:AJ30,"SL") -> 0 | AU30: 2 | AV30: =COUNTIF(F30:AJ30,"CL") -> 0 | AW30: 2 | AX30: =AK30+AL30+(AM30+AN30+AO30+AP30+AQ30+AR30+AT30+AV30) -> 0 | AY30: =AX30-AL30-(AM30/2) -> 0
... AK62: =COUNTIF(F62:AJ62,"P") -> 0 | AL62: =COUNTIF(F62:AJ62,"L") -> 0 | AM62: =COUNTIF(F62:AJ62,"HD") -> 0 | AN62: =COUNTIF(F62:AJ62,"NH") -> 0 | AO62: =COUNTIF(F62:AJ62,"FH") -> 0 | AP62: =COUNTIF(F62:AJ62,"T") -> 0 | AQ62: =COUNTIF(F62:AJ62,"ML") -> 0 | AR62: =COUNTIF(F62:AJ62,"EL") -> 0 | AS62: 1 | AT62: =COUNTIF(F62:AJ62,"SL") -> 0 | AU62: 2 | AV62: =COUNTIF(F62:AJ62,"CL") -> 0 | AW62: 2 | AX62: =AK62+AL62+(AM62+AN62+AO62+AP62+AQ62+AR62+AT62+AV62) -> 0 | AY62: =AX62-AL62-(AM62/2) -> 0
A64: Daily Attendance | F64: =COUNTIF(F13:F62,"P") -> 0 | G64: =COUNTIF(G13:G62,"P") -> 0 | H64: =COUNTIF(H13:H62,"P") -> 0 | I64: =COUNTIF(I13:I62,"P") -> 0 | J64: =COUNTIF(J13:J62,"P") -> 0 | K64: =COUNTIF(K13:K62,"P") -> 0 | L64: =COUNTIF(L13:L62,"P") -> 0 | M64: =COUNTIF(M13:M62,"P") -> 0 | ... AJ64: =COUNTIF(AJ13:AJ62,"P") -> 6

Sheet Feb '25
E1: JAIKALKI TECHNOLOGY PVT. LTD.
E2: Employee Attendance Sheet
B3: =HLOOKUP(B6,$E$3:$O$4,2,0) -> 2 | E3: January | F3: February | G3: March | H3: April | I3: May | J3: June | K3: July | L3: August | M3: September | N3: October | O3: Novemeber | P3: December
E4: 1 | F4: 2 | G4: 3 | H4: 4 | I4: 5 | J4: 6 | K4: 7 | L4: 8 | M4: 9 | N4: 10 | O4: 11 | P4: 12
A5: Year | B5: 2025 | C5: D O B | D5: D O J | E5: Date | F5: 1 | G5: 2 | H5: 3 | I5: 4 | J5: 5 | K5: 6 | L5: 7 | M5: 8 | N5: 9 | O5: 10 | P5: 11 | Q5: 12 | R5: 13 | S5: 14 | T5: 15 | U5: 16 | V5: 17 | W5: 18 | X5: 19 | Y5: 20 | Z5: 21 | AA5: 22 | AB5: 23 | AC5: 24 | AD5: 25 | AE5: 26 | AF5: 27 | AG5: 28 | AH5: 29 | AI5: 30 | AJ5: 31 | AK5: Monthly Attendance Summary
A6: Month | B6: February | E6: Type of Day | F6: =IF(F7="Sun","H","W") -> W | G6: =IF(G7="Sun","H","W") -> H | H6: =IF(H7="Sun","H","W") -> W | I6: =IF(I7="Sun","H","W") -> W | J6: =IF(J7="Sun","H","W") -> W | K6: =IF(K7="Sun","H","W") -> W | L6: =IF(L7="Sun","H","W") -> W | M6: =IF(M7="Sun","H","W") -> W | ... AJ6: =IF(AJ7="Sun","H","W") -> W
A7: Emp. ID | B7: Employee Name | E7: Month | F7: =IFERROR(TEXT(DATE($B$5,$B$3,F$5),"ddd"),"") -> Sat | G7: =IFERROR(TEXT(DATE($B$5,$B$3,G$5),"ddd"),"") -> Sun | H7: =IFERROR(TEXT(DATE($B$5,$B$3,H$5),"ddd"),"") -> Mon | I7: =IFERROR(TEXT(DATE($B$5,$B$3,I$5),"ddd"),"") -> Tue | J7: =IFERROR(TEXT(DATE($B$5,$B$3,J$5),"ddd"),"") -> Wed | K7: =IFERROR(TEXT(DATE($B$5,$B$3,K$5),"ddd"),"") -> Thu | L7: =IFERROR(TEXT(DATE($B$5,$B$3,L$5),"ddd"),"") -> Fri | M7: =IFERROR(TEXT(DATE($B$5,$B$3,M$5),"ddd"),"") -> Sat | ... AJ7: =IFERROR(TEXT(DATE($B$5,$B$3,AJ$5),"ddd"),"") -> Mon | AK7: P | AL7: L | AM7: HD | AN7: NH | AO7: FH | AP7: T | AQ7: ML | AR7: EL | AS7: EL AL | AT7: SL | AU7: SL AL | AV7: CL | AW7: CL AL | AX7: Working Days | AY7: Days Payable
A8: JKT001 | B8: Shyamveer Singh | C8: 11th Sept 1991 | D8: 14th Sept 2024 | E8: =$B$6 -> February | F8: P | G8: P | H8: P | I8: P | J8: P | K8: P | L8: P | M8: P | N8: P | O8: P | P8: P | Q8: P | R8: P | S8: P | T8: P | U8: P | V8: P | W8: P | X8: P | Y8: P | Z8: P | AA8: P | AB8: P | AC8: P | AD8: P | AE8: P | AF8: P | AG8: P | AK8: =COUNTIF(F8:AJ8,"P") -> 28 | AL8: =COUNTIF(F8:AJ8,"L") -> 0 | AM8: =COUNTIF(F8:AJ8,"HD") -> 0 | AN8: =COUNTIF(F8:AJ8,"NH") -> 0 | AO8: =COUNTIF(F8:AJ8,"FH") -> 0 | AP8: =COUNTIF(F8:AJ8,"T") -> 0 | AQ8: =COUNTIF(F8:AJ8,"ML") -> 0 | AR8: =COUNTIF(F8:AJ8,"EL") -> 0 | AS8: 1 | AT8: =COUNTIF(O8:AS8,"SL") -> 0 | AU8: 2 | AV8: =COUNTIF(F8:AJ8,"CL") -> 0 | AW8: 2 | AX8: =AK8+AL8+(AM8+AN8+AO8+AP8+AQ8+AR8+AT8+AV8) -> 28 | AY8: =AX8-AL8-(AM8/2) -> 28
A9: JKT002 | B9: Rohitkumar Kannojiya | C9: 10th May 2001 | D9: 14th Sept 2024 | E9: =$B$6 -> February | F9: P | G9: P | H9: P | I9: P | J9: P | K9: P | L9: P | M9: P | N9: P | O9: P | P9: P | Q9: P | R9: P | S9: P | T9: P | U9: P | V9: P | W9: P | X9: P | Y9: P | Z9: P | AA9: P | AB9: P | AC9: P | AD9: P | AE9: P | AF9: P | AG9: P | AK9: =COUNTIF(F9:AJ9,"P") -> 28 | AL9: =COUNTIF(F9:AJ9,"L") -> 0 | AM9: =COUNTIF(F9:AJ9,"HD") -> 0 | AN9: =COUNTIF(F9:AJ9,"NH") -> 0 | AO9: =COUNTIF(F9:AJ9,"FH") -> 0 | AP9: =COUNTIF(F9:AJ9,"T") -> 0 | AQ9: =COUNTIF(F9:AJ9,"ML") -> 0 | AR9: =COUNTIF(F9:AJ9,"EL") -> 0 | AS9: 1 | AT9: =COUNTIF(O9:AS9,"SL") -> 0 | AU9: 2 | AV9: =COUNTIF(F9:AJ9,"CL") -> 0 | AW9: 2 | AX9: =AK9+AL9+(AM9+AN9+AO9+AP9+AQ9+AR9+AT9+AV9) -> 28 | AY9: =AX9-AL9-(AM9/2) -> 28
A10: JKT003 | B10: Krunal Trivedi | C10: 29th May 1987 | D10: 14th Sept 2024 | E10: =$B$6 -> February | F10: P | G10: P | H10: P | I10: P | J10: P | K10: P | L10: P | M10: P | N10: P | O10: P | P10: P | Q10: P | R10: P | S10: P | T10: P | U10: P | V10: P | W10: P | X10: P | Y10: P | Z10: P | AA10: P | AB10: P | AC10: P | AD10: P | AE10: P | AF10: P | AG10: P | AK10: =COUNTIF(F10:AJ10,"P") -> 28 | AL10: =COUNTIF(F10:AJ10,"L") -> 0 | AM10: =COUNTIF(F10:AJ10,"HD") -> 0 | AN10: =COUNTIF(F10:AJ10,"NH") -> 0 | AO10: =COUNTIF(F10:AJ10,"FH") -> 0 | AP10: =COUNTIF(F10:AJ10,"T") -> 0 | AQ10: =COUNTIF(F10:AJ10,"ML") -> 0 | AR10: =COUNTIF(F10:AJ10,"EL") -> 0 | AS10: 1 | AT10: =COUNTIF(O10:AS10,"SL") -> 0 | AU10: 2 | AV10: =COUNTIF(F10:AJ10,"CL") -> 0 | AW10: 2 | AX10: =AK10+AL10+(AM10+AN10+AO10+AP10+AQ10+AR10+AT10+AV10) -> 28 | AY10: =AX10-AL10-(AM10/2) -> 28
A11: JKT004 | B11: Ranjeetkumar Yadav | C11: 27th Mar 1987 | D11: 14th Sept 2024 | E11: =$B$6 -> February | F11: P | G11: P | H11: P | I11: P | J11: P | K11: P | L11: P | M11: P | N11: P | O11: P | P11: P | Q11: P | R11: P | S11: P | T11: P | U11: P | V11: P | W11: P | X11: P | Y11: P | Z11: P | AA11: P | AB11: P | AC11: P | AD11: P | AE11: P | AF11: P | AG11: P | AK11: =COUNTIF(F11:AJ11,"P") -> 28 | AL11: =COUNTIF(F11:AJ11,"L") -> 0 | AM11: =COUNTIF(F11:AJ11,"HD") -> 0 | AN11: =COUNTIF(F11:AJ11,"NH") -> 0 | AO11: =COUNTIF(F11:AJ11,"FH") -> 0 | AP11: =COUNTIF(F11:AJ11,"T") -> 0 | AQ11: =COUNTIF(F11:AJ11,"ML") -> 0 | AR11: =COUNTIF(F11:AJ11,"EL") -> 0 | AS11: 1 | AT11: =COUNTIF(O11:AS11,"SL") -> 0 | AU11: 2 | AV11: =COUNTIF(F11:AJ11,"CL") -> 0 | AW11: 2 | AX11: =AK11+AL11+(AM11+AN11+AO11+AP11+AQ11+AR11+AT11+AV11) -> 28 | AY11: =AX11-AL11-(AM11/2) -> 28
A12: JKT005 | B12: Santosh Vishwakarma | C12: 4th Jul 1998 | D12: 14th Sept 2024 | E12: =$B$6 -> February | F12: P | G12: P | H12: P | I12: P | J12: P | K12: P | L12: P | M12: P | N12: P | O12: P | P12: P | Q12: P | R12: P | S12: P | T12: P | U12: P | V12: P | W12: P | X12: P | Y12: P | Z12: P | AA12: P | AB12: P | AC12: P | AD12: P | AE12: P | AF12: P | AG12: P | AK12: =COUNTIF(F12:AJ12,"P") -> 28 | AL12: =COUNTIF(F12:AJ12,"L") -> 0 | AM12: =COUNTIF(F12:AJ12,"HD") -> 0 | AN12: =COUNTIF(F12:AJ12,"NH") -> 0 | AO12: =COUNTIF(F12:AJ12,"FH") -> 0 | AP12: =COUNTIF(F12:AJ12,"T") -> 0 | AQ12: =COUNTIF(F12:AJ12,"ML") -> 0 | AR12: =COUNTIF(F12:AJ12,"EL") -> 0 | AS12: 1 | AT12: =COUNTIF(O12:AS12,"SL") -> 0 | AU12: 2 | AV12: =COUNTIF(F12:AJ12,"CL") -> 0 | AW12: 2 | AX12: =AK12+AL12+(AM12+AN12+AO12+AP12+AQ12+AR12+AT12+AV12) -> 28 | AY12: =AX12-AL12-(AM12/2) -> 28
A13: JKT006 | B13: Deepak Borana | C13: 23rd June 2000 | D13: 6th Jan 2025 | E13: =$B$6 -> February | F13: P | G13: P | H13: P | I13: P | J13: P | K13: P | L13: P | M13: P | N13: P | O13: P | P13: P | Q13: P | R13: P | S13: L | T13: P | U13: P | V13: P | W13: P | X13: P | Y13: P | Z13: P | AA13: P | AB13: P | AC13: P | AD13: P | AE13: P | AF13: P | AG13: P | AK13: =COUNTIF(F13:AJ13,"P") -> 27 | AL13: =COUNTIF(F13:AJ13,"L") -> 1 | AM13: =COUNTIF(F13:AJ13,"HD") -> 0 | AN13: =COUNTIF(F13:AJ13,"NH") -> 0 | AO13: =COUNTIF(F13:AJ13,"FH") -> 0 | AP13: =COUNTIF(F13:AJ13,"T") -> 0 | AQ13: =COUNTIF(F13:AJ13,"ML") -> 0 | AR13: =COUNTIF(F13:AJ13,"EL") -> 0 | AS13: 1 | AT13: =COUNTIF(F13:AJ13,"SL") -> 0 | AU13: 2 | AV13: =COUNTIF(F13:AJ13,"CL") -> 0 | AW13: 2 | AX13: =AK13+AL13+(AM13+AN13+AO13+AP13+AQ13+AR13+AT13+AV13) -> 28 | AY13: =AX13-AL13-(AM13/2) -> 27
A14: JKT007 | B14: Jincy Mathew | C14: 19th April 1999 | D14: 13th Jan 2025 | E14: =$B$6 -> February | F14: L | G14: P | H14: P | I14: L | J14: L | K14: L | L14: P | M14: L | N14: P | O14: P | P14: L | Q14: L | R14: P | S14: P | T14: L | U14: P | V14: P | W14: L | X14: L | Y14: P | Z14: P | AA14: L | AB14: P | AC14: P | AD14: P | AE14: L | AF14: P | AG14: P | AK14: =COUNTIF(F14:AJ14,"P") -> 16 | AL14: =COUNTIF(F14:AJ14,"L") -> 12 | AM14: =COUNTIF(F14:AJ14,"HD") -> 0 | AN14: =COUNTIF(F14:AJ14,"NH") -> 0 | AO14: =COUNTIF(F14:AJ14,"FH") -> 0 | AP14: =COUNTIF(F14:AJ14,"T") -> 0 | AQ14: =COUNTIF(F14:AJ14,"ML") -> 0 | AR14: =COUNTIF(F14:AJ14,"EL") -> 0 | AS14: 1 | AT14: =COUNTIF(F14:AJ14,"SL") -> 0 | AU14: 2 | AV14: =COUNTIF(F14:AJ14,"CL") -> 0 | AW14: 2 | AX14: =AK14+AL14+(AM14+AN14+AO14+AP14+AQ14+AR14+AT14+AV14) -> 28 | AY14: =AX14-AL14-(AM14/2) -> 16
A15: JKT008 | B15: Sanjay Jaiswar | C15: 18th Feb 2002 | D15: 16th Jan 2025 | E15: =$B$6 -> February | F15: P | G15: P | H15: P | I15: P | J15: P | K15: P | L15: P | M15: P | N15: P | O15: P | P15: P | Q15: P | R15: P | S15: P | T15: P | U15: P | V15: P | W15: P | X15: P | Y15: P | Z15: P | AA15: P | AB15: P | AC15: P | AD15: P | AE15: P | AF15: P | AG15: P | AK15: =COUNTIF(F15:AJ15,"P") -> 28 | AL15: =COUNTIF(F15:AJ15,"L") -> 0 | AM15: =COUNTIF(F15:AJ15,"HD") -> 0 | AN15: =COUNTIF(F15:AJ15,"NH") -> 0 | AO15: =COUNTIF(F15:AJ15,"FH") -> 0 | AP15: =COUNTIF(F15:AJ15,"T") -> 0 | AQ15: =COUNTIF(F15:AJ15,"ML") -> 0 | AR15: =COUNTIF(F15:AJ15,"EL") -> 0 | AS15: 1 | AT15: =COUNTIF(F15:AJ15,"SL") -> 0 | AU15: 2 | AV15: =COUNTIF(F15:AJ15,"CL") -> 0 | AW15: 2 | AX15: =AK15+AL15+(AM15+AN15+AO15+AP15+AQ15+AR15+AT15+AV15) -> 28 | AY15: =AX15-AL15-(AM15/2) -> 28
A16: JKT009 | B16: Chauhan Badal | C16: 12th Mar 2002 | D16: 30th Jan 2025 | E16: =$B$6 -> February | F16: P | G16: P | H16: P | I16: P | J16: P | K16: P | L16: P | M16: P | N16: P | O16: P | P16: P | Q16: P | R16: P | S16: P | T16: L | U16: P | V16: P | W16: P | X16: P | Y16: P | Z16: P | AA16: P | AB16: P | AC16: P | AD16: L | AE16: P | AF16: P | AG16: P | AK16: =COUNTIF(F16:AJ16,"P") -> 26 | AL16: =COUNTIF(F16:AJ16,"L") -> 2 | AM16: =COUNTIF(F16:AJ16,"HD") -> 0 | AN16: =COUNTIF(F16:AJ16,"NH") -> 0 | AO16: =COUNTIF(F16:AJ16,"FH") -> 0 | AP16: =COUNTIF(F16:AJ16,"T") -> 0 | AQ16: =COUNTIF(F16:AJ16,"ML") -> 0 | AR16: =COUNTIF(F16:AJ16,"EL") -> 0 | AS16: 1 | AT16: =COUNTIF(F16:AJ16,"SL") -> 0 | AU16: 2 | AV16: =COUNTIF(F16:AJ16,"CL") -> 0 | AW16: 2 | AX16: =AK16+AL16+(AM16+AN16+AO16+AP16+AQ16+AR16+AT16+AV16) -> 28 | AY16: =AX16-AL16-(AM16/2) -> 26
A17: JKT010 | B17: Vikas Kotiyan | C17: 18th Sept 1999 | D17: 17th Mar 2025 | E17: =$B$6 -> February | AK17: =COUNTIF(F17:AJ17,"P") -> 0 | AL17: =COUNTIF(F17:AJ17,"L") -> 0 | AM17: =COUNTIF(F17:AJ17,"HD") -> 0 | AN17: =COUNTIF(F17:AJ17,"NH") -> 0 | AO17: =COUNTIF(F17:AJ17,"FH") -> 0 | AP17: =COUNTIF(F17:AJ17,"T") -> 0 | AQ17: =COUNTIF(F17:AJ17,"ML") -> 0 | AR17: =COUNTIF(F17:AJ17,"EL") -> 0 | AS17: 1 | AT17: =COUNTIF(F17:AJ17,"SL") -> 0 | AU17: 2 | AV17: =COUNTIF(F17:AJ17,"CL") -> 0 | AW17: 2 | AX17: =AK17+AL17+(AM17+AN17+AO17+AP17+AQ17+AR17+AT17+AV17) -> 0 | AY17: =AX17-AL17-(AM17/2) -> 0
A18: JKT011 | B18: Pratibha Tiwari | C18: 14th Feb 2004 | D18: 17th Apr 2025 | E18: =$B$6 -> February | AK18: =COUNTIF(F18:AJ18,"P") -> 0 | AL18: =COUNTIF(F18:AJ18,"L") -> 0 | AM18: =COUNTIF(F18:AJ18,"HD") -> 0 | AN18: =COUNTIF(F18:AJ18,"NH") -> 0 | AO18: =COUNTIF(F18:AJ18,"FH") -> 0 | AP18: =COUNTIF(F18:AJ18,"T") -> 0 | AQ18: =COUNTIF(F18:AJ18,"ML") -> 0 | AR18: =COUNTIF(F18:AJ18,"EL") -> 0 | AS18: 1 | AT18: =COUNTIF(F18:AJ18,"SL") -> 0 | AU18: 2 | AV18: =COUNTIF(F18:AJ18,"CL") -> 0 | AW18: 2 | AX18: =AK18+AL18+(AM18+AN18+AO18+AP18+AQ18+AR18+AT18+AV18) -> 0 | AY18: =AX18-AL18-(AM18/2) -> 0
AK19: =COUNTIF(F19:AJ19,"P") -> 0 | AL19: =COUNTIF(F19:AJ19,"L") -> 0 | AM19: =COUNTIF(F19:AJ19,"HD") -> 0 | AN19: =COUNTIF(F19:AJ19,"NH") -> 0 | AO19: =COUNTIF(F19:AJ19,"FH") -> 0 | AP19: =COUNTIF(F19:AJ19,"T") -> 0 | AQ19: =COUNTIF(F19:AJ19,"ML") -> 0 | AR19: =COUNTIF(F19:AJ19,"EL") -> 0 | AS19: 1 | AT19: =COUNTIF(F19:AJ19,"SL") -> 0 | AU19: 2 | AV19: =COUNTIF(F19:AJ19,"CL") -> 0 | AW19: 2 | AX19: =AK19+AL19+(AM19+AN19+AO19+AP19+AQ19+AR19+AT19+AV19) -> 0 | AY19: =AX19-AL19-(AM19/2) -> 0
AK20: =COUNTIF(F20:AJ20,"P") -> 0 | AL20: =COUNTIF(F20:AJ20,"L") -> 0 | AM20: =COUNTIF(F20:AJ20,"HD") -> 0 | AN20: =COUNTIF(F20:AJ20,"NH") -> 0 | AO20: =COUNTIF(F20:AJ20,"FH") -> 0 | AP20: =COUNTIF(F20:AJ20,"T") -> 0 | AQ20: =COUNTIF(F20:AJ20,"ML") -> 0 | AR20: =COUNTIF(F20:AJ20,"EL") -> 0 | AS20: 1 | AT20: =COUNTIF(F20:AJ20,"SL") -> 0 | AU20: 2 | AV20: =COUNTIF(F20:AJ20,"CL") -> 0 | AW20: 2 | AX20: =AK20+AL20+(AM20+AN20+AO20+AP20+AQ20+AR20+AT20+AV20) -> 0 | AY20: =AX20-AL20-(AM20/2) -> 0
AK21: =COUNTIF(F21:AJ21,"P") -> 0 | AL21: =COUNTIF(F21:AJ21,"L") -> 0 | AM21: =COUNTIF(F21:AJ21,"HD") -> 0 | AN21: =COUNTIF(F21:AJ21,"NH") -> 0 | AO21: =COUNTIF(F21:AJ21,"FH") -> 0 | AP21: =COUNTIF(F21:AJ21,"T") -> 0 | AQ21: =COUNTIF(F21:AJ21,"ML") -> 0 | AR21: =COUNTIF(F21:AJ21,"EL") -> 0 | AS21: 1 | AT21: =COUNTIF(F21:AJ21,"SL") -> 0 | AU21: 2 | AV21: =COUNTIF(F21:AJ21,"CL") -> 0 | AW21: 2 | AX21: =AK21+AL21+(AM21+AN21+AO21+AP21+AQ21+AR21+AT21+AV21) -> 0 | AY21: =AX21-AL21-(AM21/2) -> 0
AK22: =COUNTIF(F22:AJ22,"P") -> 0 | AL22: =COUNTIF(F22:AJ22,"L") -> 0 | AM22: =COUNTIF(F22:AJ22,"HD") -> 0 | AN22: =COUNTIF(F22:AJ22,"NH") -> 0 | AO22: =COUNTIF(F22:AJ22,"FH") -> 0 | AP22: =COUNTIF(F22:AJ22,"T") -> 0 | AQ22: =COUNTIF(F22:AJ22,"ML") -> 0 | AR22: =COUNTIF(F22:AJ22,"EL") -> 0 | AS22: 1 | AT22: =COUNTIF(F22:AJ22,"SL") -> 0 | AU22: 2 | AV22: =COUNTIF(F22:AJ22,"CL") -> 0 | AW22: 2 | AX22: =AK22+AL22+(AM22+AN22+AO22+AP22+AQ22+AR22+AT22+AV22) -> 0 | AY22: =AX22-AL22-(AM22/2) -> 0
AK23: =COUNTIF(F23:AJ23,"P") -> 0 | AL23: =COUNTIF(F23:AJ23,"L") -> 0 | AM23: =COUNTIF(F23:AJ23,"HD") -> 0 | AN23: =COUNTIF(F23:AJ23,"NH") -> 0 | AO23: =COUNTIF(F23:AJ23,"FH") -> 0 | AP23: =COUNTIF(F23:AJ23,"T") -> 0 | AQ23: =COUNTIF(F23:AJ23,"ML") -> 0 | AR23: =COUNTIF(F23:AJ23,"EL") -> 0 | AS23: 1 | AT23: =COUNTIF(F23:AJ23,"SL") -> 0 | AU23: 2 | AV23: =COUNTIF(F23:AJ23,"CL") -> 0 | AW23: 2 | AX23: =AK23+AL23+(AM23+AN23+AO23+AP23+AQ23+AR23+AT23+AV23) -> 0 | AY23: =AX23-AL23-(AM23/2) -> 0
AK24: =COUNTIF(F24:AJ24,"P") -> 0 | AL24: =COUNTIF(F24:AJ24,"L") -> 0 | AM24: =COUNTIF(F24:AJ24,"HD") -> 0 | AN24: =COUNTIF(F24:AJ24,"NH") -> 0 | AO24: =COUNTIF(F24:AJ24,"FH") -> 0 | AP24: =COUNTIF(F24:AJ24,"T") -> 0 | AQ24: =COUNTIF(F24:AJ24,"ML") -> 0 | AR24: =COUNTIF(F24:AJ24,"EL") -> 0 | AS24: 1 | AT24: =COUNTIF(F24:AJ24,"SL") -> 0 | AU24: 2 | AV24: =COUNTIF(F24:AJ24,"CL") -> 0 | AW24: 2 | AX24: =AK24+AL24+(AM24+AN24+AO24+AP24+AQ24+AR24+AT24+AV24) -> 0 | AY24: =AX24-AL24-(AM24/2) -> 0
AK25: =COUNTIF(F25:AJ25,"P") -> 0 | AL25: =COUNTIF(F25:AJ25,"L") -> 0 | AM25: =COUNTIF(F25:AJ25,"HD") -> 0 | AN25: =COUNTIF(F25:AJ25,"NH") -> 0 | AO25: =COUNTIF(F25:AJ25,"FH") -> 0 | AP25: =COUNTIF(F25:AJ25,"T") -> 0 | AQ25: =COUNTIF(F25:AJ25,"ML") -> 0 | AR25: =COUNTIF(F25:AJ25,"EL") -> 0 | AS25: 1 | AT25: =COUNTIF(F25:AJ25,"SL") -> 0 | AU25: 2 | AV25: =COUNTIF(F25:AJ25,"CL") -> 0 | AW25: 2 | AX25: =AK25+AL25+(AM25+AN25+AO25+AP25+AQ25+AR25+AT25+AV25) -> 0 | AY25: =AX25-AL25-(AM25/2) -> 0
AK26: =COUNTIF(F26:AJ26,"P") -> 0 | AL26: =COUNTIF(F26:AJ26,"L") -> 0 | AM26: =COUNTIF(F26:AJ26,"HD") -> 0 | AN26: =COUNTIF(F26:AJ26,"NH") -> 0 | AO26: =COUNTIF(F26:AJ26,"FH") -> 0 | AP26: =COUNTIF(F26:AJ26,"T") -> 0 | AQ26: =COUNTIF(F26:AJ26,"ML") -> 0 | AR26: =COUNTIF(F26:AJ26,"EL") -> 0 | AS26: 1 | AT26: =COUNTIF(F26:AJ26,"SL") -> 0 | AU26: 2 | AV26: =COUNTIF(F26:AJ26,"CL") -> 0 | AW26: 2 | AX26: =AK26+AL26+(AM26+AN26+AO26+AP26+AQ26+AR26+AT26+AV26) -> 0 | AY26: =AX26-AL26-(AM26/2) -> 0
AK27: =COUNTIF(F27:AJ27,"P") -> 0 | AL27: =COUNTIF(F27:AJ27,"L") -> 0 | AM27: =COUNTIF(F27:AJ27,"HD") -> 0 | AN27: =COUNTIF(F27:AJ27,"NH") -> 0 | AO27: =COUNTIF(F27:AJ27,"FH") -> 0 | AP27: =COUNTIF(F27:AJ27,"T") -> 0 | AQ27: =COUNTIF(F27:AJ27,"ML") -> 0 | AR27: =COUNTIF(F27:AJ27,"EL") -> 0 | AS27: 1 | AT27: =COUNTIF(F27:AJ27,"SL") -> 0 | AU27: 2 | AV27: =COUNTIF(F27:AJ27,"CL") -> 0 | AW27: 2 | AX27: =AK27+AL27+(AM27+AN27+AO27+AP27+AQ27+AR27+AT27+AV27) -> 0 | AY27: =AX27-AL27-(AM27/2) -> 0
AK28: =COUNTIF(F28:AJ28,"P") -> 0 | AL28: =COUNTIF(F28:AJ28,"L") -> 0 | AM28: =COUNTIF(F28:AJ28,"HD") -> 0 | AN28: =COUNTIF(F28:AJ28,"NH") -> 0 | AO28: =COUNTIF(F28:AJ28,"FH") -> 0 | AP28: =COUNTIF(F28:AJ28,"T") -> 0 | AQ28: =COUNTIF(F28:AJ28,"ML") -> 0 | AR28: =COUNTIF(F28:AJ28,"EL") -> 0 | AS28: 1 | AT28: =COUNTIF(F28:AJ28,"SL") -> 0 | AU28: 2 | AV28: =COUNTIF(F28:AJ28,"CL") -> 0 | AW28: 2 | AX28: =AK28+AL28+(AM28+AN28+AO28+AP28+AQ28+AR28+AT28+AV28) -> 0 | AY28: =AX28-AL28-(AM28/2) -> 0
AK29: =COUNTIF(F29:AJ29,"P") -> 0 | AL29: =COUNTIF(F29:AJ29,"L") -> 0 | AM29: =COUNTIF(F29:AJ29,"HD") -> 0 | AN29: =COUNTIF(F29:AJ29,"NH") -> 0 | AO29: =COUNTIF(F29:AJ29,"FH") -> 0 | AP29: =COUNTIF(F29:AJ29,"T") -> 0 | AQ29: =COUNTIF(F29:AJ29,"ML") -> 0 | AR29: =COUNTIF(F29:AJ29,"EL") -> 0 | AS29: 1 | AT29: =COUNTIF(F29:AJ29,"SL") -> 0 | AU29: 2 | AV29: =COUNTIF(F29:AJ29,"CL") -> 0 | AW29: 2 | AX29: =AK29+AL29+(AM29+AN29+AO29+AP29+AQ29+AR29+AT29+AV29) -> 0 | AY29: =AX29-AL29-(AM29/2) -> 0
AK30: =COUNTIF(F30:AJ30,"P") -> 0 | AL30: =COUNTIF(F30:AJ30,"L") -> 0 | AM30: =COUNTIF(F30:AJ30,"HD") -> 0 | AN30: =COUNTIF(F30:AJ30,"NH") -> 0 | AO30: =COUNTIF(F30:AJ30,"FH") -> 0 | AP30: =COUNTIF(F30:AJ30,"T") -> 0 | AQ30: =COUNTIF(F30:AJ30,"ML") -> 0 | AR30: =COUNTIF(F30:AJ30,"EL") -> 0 | AS30: 1 | AT30: =COUNTIF(F30:AJ30,"SL") -> 0 | AU30: 2 | AV30: =COUNTIF(F30:AJ30,"CL") -> 0 | AW30: 2 | AX30: =AK30+AL30+(AM30+AN30+AO30+AP30+AQ30+AR30+AT30+AV30) -> 0 | AY30: =AX30-AL30-(AM30/2) -> 0
... AK62: =COUNTIF(F62:AJ62,"P") -> 0 | AL62: =COUNTIF(F62:AJ62,"L") -> 0 | AM62: =COUNTIF(F62:AJ62,"HD") -> 0 | AN62: =COUNTIF(F62:AJ62,"NH") -> 0 | AO62: =COUNTIF(F62:AJ62,"FH") -> 0 | AP62: =COUNTIF(F62:AJ62,"T") -> 0 | AQ62: =COUNTIF(F62:AJ62,"ML") -> 0 | AR62: =COUNTIF(F62:AJ62,"EL") -> 0 | AS62: 1 | AT62: =COUNTIF(F62:AJ62,"SL") -> 0 | AU62: 2 | AV62: =COUNTIF(F62:AJ62,"CL") -> 0 | AW62: 2 | AX62: =AK62+AL62+(AM62+AN62+AO62+AP62+AQ62+AR62+AT62+AV62) -> 0 | AY62: =AX62-AL62-(AM62/2) -> 0
A64: Daily Attendance | F64: =COUNTIF(F13:F62,"P") -> 3 | G64: =COUNTIF(G13:G62,"P") -> 4 | H64: =COUNTIF(H13:H62,"P") -> 4 | I64: =COUNTIF(I13:I62,"P") -> 3 | J64: =COUNTIF(J13:J62,"P") -> 3 | K64: =COUNTIF(K13:K62,"P") -> 3 | L64: =COUNTIF(L13:L62,"P") -> 4 | M64: =COUNTIF(M13:M62,"P") -> 3 | ... AJ64: =COUNTIF(AJ13:AJ62,"P") -> 0

Sheet Mar '25
E1: JAIKALKI TECHNOLOGY PVT. LTD.
E2: Employee Attendance Sheet
B3: =HLOOKUP(B6,$E$3:$O$4,2,0) -> 3 | E3: January | F3: February | G3: March | H3: April | I3: May | J3: June | K3: July | L3: August | M3: September | N3: October | O3: Novemeber | P3: December
E4: 1 | F4: 2 | G4: 3 | H4: 4 | I4: 5 | J4: 6 | K4: 7 | L4: 8 | M4: 9 | N4: 10 | O4: 11 | P4: 12
A5: Year | B5: 2025 | C5: D O B | D5: D O J | E5: Date | F5: 1 | G5: 2 | H5: 3 | I5: 4 | J5: 5 | K5: 6 | L5: 7 | M5: 8 | N5: 9 | O5: 10 | P5: 11 | Q5: 12 | R5: 13 | S5: 14 | T5: 15 | U5: 16 | V5: 17 | W5: 18 | X5: 19 | Y5: 20 | Z5: 21 | AA5: 22 | AB5: 23 | AC5: 24 | AD5: 25 | AE5: 26 | AF5: 27 | AG5: 28 | AH5: 29 | AI5: 30 | AJ5: 31 | AK5: Monthly Attendance Summary
A6: Month | B6: March | E6: Type of Day | F6: =IF(F7="Sun","H","W") -> W | G6: =IF(G7="Sun","H","W") -> H | H6: =IF(H7="Sun","H","W") -> W | I6: =IF(I7="Sun","H","W") -> W | J6: =IF(J7="Sun","H","W") -> W | K6: =IF(K7="Sun","H","W") -> W | L6: =IF(L7="Sun","H","W") -> W | M6: =IF(M7="Sun","H","W") -> W | ... AJ6: =IF(AJ7="Sun","H","W") -> W
A7: Emp. ID | B7: Employee Name | E7: Month | F7: =IFERROR(TEXT(DATE($B$5,$B$3,F$5),"ddd"),"") -> Sat | G7: =IFERROR(TEXT(DATE($B$5,$B$3,G$5),"ddd"),"") -> Sun | H7: =IFERROR(TEXT(DATE($B$5,$B$3,H$5),"ddd"),"") -> Mon | I7: =IFERROR(TEXT(DATE($B$5,$B$3,I$5),"ddd"),"") -> Tue | J7: =IFERROR(TEXT(DATE($B$5,$B$3,J$5),"ddd"),"") -> Wed | K7: =IFERROR(TEXT(DATE($B$5,$B$3,K$5),"ddd"),"") -> Thu | L7: =IFERROR(TEXT(DATE($B$5,$B$3,L$5),"ddd"),"") -> Fri | M7: =IFERROR(TEXT(DATE($B$5,$B$3,M$5),"ddd"),"") -> Sat | ... AJ7: =IFERROR(TEXT(DATE($B$5,$B$3,AJ$5),"ddd"),"") -> Mon | AK7: P | AL7: L | AM7: HD | AN7: NH | AO7: FH | AP7: T | AQ7: ML | AR7: EL | AS7: EL AL | AT7: SL | AU7: SL AL | AV7: CL | AW7: CL AL | AX7: Working Days | AY7: Days Payable
A8: JKT001 | B8: Shyamveer Singh | C8: 11th Sept 1991 | D8: 14th Sept 2024 | E8: =$B$6 -> March | F8: P | G8: P | H8: P | I8: P | J8: P | K8: P | L8: P | M8: P | N8: P | O8: P | P8: P | Q8: P | R8: P | S8: P | T8: P | U8: P | V8: P | W8: P | X8: P | Y8: P | Z8: P | AA8: P | AB8: P | AC8: P | AD8: P | AE8: P | AF8: P | AG8: P | AH8: P | AI8: P | AJ8: P | AK8: =COUNTIF(F8:AJ8,"P") -> 31 | AL8: =COUNTIF(F8:AJ8,"L") -> 0 | AM8: =COUNTIF(F8:AJ8,"HD") -> 0 | AN8: =COUNTIF(F8:AJ8,"NH") -> 0 | AO8: =COUNTIF(F8:AJ8,"FH") -> 0 | AP8: =COUNTIF(F8:AJ8,"T") -> 0 | AQ8: =COUNTIF(F8:AJ8,"ML") -> 0 | AR8: =COUNTIF(F8:AJ8,"EL") -> 0 | AS8: 1 | AT8: =COUNTIF(O8:AS8,"SL") -> 0 | AU8: 2 | AV8: =COUNTIF(F8:AJ8,"CL") -> 0 | AW8: 2 | AX8: =AK8+AL8+(AM8+AN8+AO8+AP8+AQ8+AR8+AT8+AV8) -> 31 | AY8: =AX8-AL8-(AM8/2) -> 31
A9: JKT002 | B9: Rohitkumar Kannojiya | C9: 10th May 2001 | D9: 14th Sept 2024 | E9: =$B$6 -> March | F9: P | G9: P | H9: P | I9: P | J9: P | K9: P | L9: P | M9: P | N9: P | O9: P | P9: P | Q9: P | R9: P | S9: P | T9: P | U9: P | V9: P | W9: P | X9: P | Y9: P | Z9: P | AA9: P | AB9: P | AC9: P | AD9: P | AE9: P | AF9: P | AG9: P | AH9: P | AI9: P | AJ9: P | AK9: =COUNTIF(F9:AJ9,"P") -> 31 | AL9: =COUNTIF(F9:AJ9,"L") -> 0 | AM9: =COUNTIF(F9:AJ9,"HD") -> 0 | AN9: =COUNTIF(F9:AJ9,"NH") -> 0 | AO9: =COUNTIF(F9:AJ9,"FH") -> 0 | AP9: =COUNTIF(F9:AJ9,"T") -> 0 | AQ9: =COUNTIF(F9:AJ9,"ML") -> 0 | AR9: =COUNTIF(F9:AJ9,"EL") -> 0 | AS9: 1 | AT9: =COUNTIF(O9:AS9,"SL") -> 0 | AU9: 2 | AV9: =COUNTIF(F9:AJ9,"CL") -> 0 | AW9: 2 | AX9: =AK9+AL9+(AM9+AN9+AO9+AP9+AQ9+AR9+AT9+AV9) -> 31 | AY9: =AX9-AL9-(AM9/2) -> 31
A10: JKT003 | B10: Krunal Trivedi | C10: 29th May 1987 | D10: 14th Sept 2024 | E10: =$B$6 -> March | F10: P | G10: P | H10: P | I10: P | J10: P | K10: P | L10: P | M10: P | N10: P | O10: P | P10: P | Q10: P | R10: P | S10: P | T10: P | U10: P | V10: P | W10: P | X10: P | Y10: P | Z10: P | AA10: P | AB10: P | AC10: P | AD10: P | AE10: P | AF10: P | AG10: P | AH10: P | AI10: P | AJ10: P | AK10: =COUNTIF(F10:AJ10,"P") -> 31 | AL10: =COUNTIF(F10:AJ10,"L") -> 0 | AM10: =COUNTIF(F10:AJ10,"HD") -> 0 | AN10: =COUNTIF(F10:AJ10,"NH") -> 0 | AO10: =COUNTIF(F10:AJ10,"FH") -> 0 | AP10: =COUNTIF(F10:AJ10,"T") -> 0 | AQ10: =COUNTIF(F10:AJ10,"ML") -> 0 | AR10: =COUNTIF(F10:AJ10,"EL") -> 0 | AS10: 1 | AT10: =COUNTIF(O10:AS10,"SL") -> 0 | AU10: 2 | AV10: =COUNTIF(F10:AJ10,"CL") -> 0 | AW10: 2 | AX10: =AK10+AL10+(AM10+AN10+AO10+AP10+AQ10+AR10+AT10+AV10) -> 31 | AY10: =AX10-AL10-(AM10/2) -> 31
A11: JKT004 | B11: Ranjeetkumar Yadav | C11: 27th Mar 1987 | D11: 14th Sept 2024 | E11: =$B$6 -> March | F11: P | G11: P | H11: P | I11: P | J11: P | K11: P | L11: P | M11: P | N11: P | O11: P | P11: P | Q11: P | R11: P | S11: P | T11: P | U11: P | V11: P | W11: P | X11: P | Y11: P | Z11: P | AA11: P | AB11: P | AC11: P | AD11: P | AE11: P | AF11: P | AG11: P | AH11: P | AI11: P | AJ11: P | AK11: =COUNTIF(F11:AJ11,"P") -> 31 | AL11: =COUNTIF(F11:AJ11,"L") -> 0 | AM11: =COUNTIF(F11:AJ11,"HD") -> 0 | AN11: =COUNTIF(F11:AJ11,"NH") -> 0 | AO11: =COUNTIF(F11:AJ11,"FH") -> 0 | AP11: =COUNTIF(F11:AJ11,"T") -> 0 | AQ11: =COUNTIF(F11:AJ11,"ML") -> 0 | AR11: =COUNTIF(F11:AJ11,"EL") -> 0 | AS11: 1 | AT11: =COUNTIF(O11:AS11,"SL") -> 0 | AU11: 2 | AV11: =COUNTIF(F11:AJ11,"CL") -> 0 | AW11: 2 | AX11: =AK11+AL11+(AM11+AN11+AO11+AP11+AQ11+AR11+AT11+AV11) -> 31 | AY11: =AX11-AL11-(AM11/2) -> 31
A12: JKT005 | B12: Santosh Vishwakarma | C12: 4th Jul 1998 | D12: 14th Sept 2024 | E12: =$B$6 -> March | F12: P | G12: P | H12: P | I12: P | J12: P | K12: P | L12: P | M12: P | N12: P | O12: P | P12: P | Q12: P | R12: P | S12: P | T12: P | U12: P | V12: P | W12: P | X12: P | Y12: P | Z12: P | AA12: P | AB12: P | AC12: P | AD12: P | AE12: P | AF12: P | AG12: P | AH12: P | AI12: P | AJ12: P | AK12: =COUNTIF(F12:AJ12,"P") -> 31 | AL12: =COUNTIF(F12:AJ12,"L") -> 0 | AM12: =COUNTIF(F12:AJ12,"HD") -> 0 | AN12: =COUNTIF(F12:AJ12,"NH") -> 0 | AO12: =COUNTIF(F12:AJ12,"FH") -> 0 | AP12: =COUNTIF(F12:AJ12,"T") -> 0 | AQ12: =COUNTIF(F12:AJ12,"ML") -> 0 | AR12: =COUNTIF(F12:AJ12,"EL") -> 0 | AS12: 1 | AT12: =COUNTIF(O12:AS12,"SL") -> 0 | AU12: 2 | AV12: =COUNTIF(F12:AJ12,"CL") -> 0 | AW12: 2 | AX12: =AK12+AL12+(AM12+AN12+AO12+AP12+AQ12+AR12+AT12+AV12) -> 31 | AY12: =AX12-AL12-(AM12/2) -> 31
A13: JKT006 | B13: Deepak Borana | C13: 23rd June 2000 | D13: 6th Jan 2025 | E13: =$B$6 -> March | F13: P | G13: P | H13: P | I13: P | J13: P | K13: P | L13: P | M13: P | N13: P | O13: P | P13: P | Q13: P | R13: P | S13: L | T13: P | U13: P | V13: P | W13: P | X13: P | Y13: P | Z13: P | AA13: P | AB13: P | AC13: P | AD13: P | AE13: P | AF13: P | AG13: P | AH13: P | AI13: P | AJ13: P | AK13: =COUNTIF(F13:AJ13,"P") -> 30 | AL13: =COUNTIF(F13:AJ13,"L") -> 1 | AM13: =COUNTIF(F13:AJ13,"HD") -> 0 | AN13: =COUNTIF(F13:AJ13,"NH") -> 0 | AO13: =COUNTIF(F13:AJ13,"FH") -> 0 | AP13: =COUNTIF(F13:AJ13,"T") -> 0 | AQ13: =COUNTIF(F13:AJ13,"ML") -> 0 | AR13: =COUNTIF(F13:AJ13,"EL") -> 0 | AS13: 1 | AT13: =COUNTIF(F13:AJ13,"SL") -> 0 | AU13: 2 | AV13: =COUNTIF(F13:AJ13,"CL") -> 0 | AW13: 2 | AX13: =AK13+AL13+(AM13+AN13+AO13+AP13+AQ13+AR13+AT13+AV13) -> 31 | AY13: =AX13-AL13-(AM13/2) -> 30
A14: JKT007 | B14: Jincy Mathew | C14: 19th April 1999 | D14: 13th Jan 2025 | E14: =$B$6 -> March | F14: L | G14: P | H14: P | I14: P | J14: P | K14: P | L14: P | M14: L | N14: P | O14: P | P14: P | Q14: P | R14: P | S14: P | T14: L | U14: P | V14: P | W14: P | X14: P | Y14: P | Z14: P | AA14: L | AB14: P | AC14: L | AD14: P | AE14: P | AF14: P | AG14: P | AH14: L | AI14: P | AJ14: P | AK14: =COUNTIF(F14:AJ14,"P") -> 25 | AL14: =COUNTIF(F14:AJ14,"L") -> 6 | AM14: =COUNTIF(F14:AJ14,"HD") -> 0 | AN14: =COUNTIF(F14:AJ14,"NH") -> 0 | AO14: =COUNTIF(F14:AJ14,"FH") -> 0 | AP14: =COUNTIF(F14:AJ14,"T") -> 0 | AQ14: =COUNTIF(F14:AJ14,"ML") -> 0 | AR14: =COUNTIF(F14:AJ14,"EL") -> 0 | AS14: 1 | AT14: =COUNTIF(F14:AJ14,"SL") -> 0 | AU14: 2 | AV14: =COUNTIF(F14:AJ14,"CL") -> 0 | AW14: 2 | AX14: =AK14+AL14+(AM14+AN14+AO14+AP14+AQ14+AR14+AT14+AV14) -> 31 | AY14: =AX14-AL14-(AM14/2) -> 25
A15: JKT008 | B15: Sanjay Jaiswar | C15: 18th Feb 2002 | D15: 16th Jan 2025 | E15: =$B$6 -> March | F15: P | G15: P | H15: P | I15: P | J15: P | K15: P | L15: P | M15: P | N15: P | O15: P | P15: P | Q15: P | R15: P | S15: P | T15: P | U15: P | V15: P | W15: P | X15: P | Y15: P | Z15: P | AA15: P | AB15: P | AC15: P | AD15: P | AE15: P | AF15: P | AG15: P | AH15: P | AI15: P | AJ15: P | AK15: =COUNTIF(F15:AJ15,"P") -> 31 | AL15: =COUNTIF(F15:AJ15,"L") -> 0 | AM15: =COUNTIF(F15:AJ15,"HD") -> 0 | AN15: =COUNTIF(F15:AJ15,"NH") -> 0 | AO15: =COUNTIF(F15:AJ15,"FH") -> 0 | AP15: =COUNTIF(F15:AJ15,"T") -> 0 | AQ15: =COUNTIF(F15:AJ15,"ML") -> 0 | AR15: =COUNTIF(F15:AJ15,"EL") -> 0 | AS15: 1 | AT15: =COUNTIF(F15:AJ15,"SL") -> 0 | AU15: 2 | AV15: =COUNTIF(F15:AJ15,"CL") -> 0 | AW15: 2 | AX15: =AK15+AL15+(AM15+AN15+AO15+AP15+AQ15+AR15+AT15+AV15) -> 31 | AY15: =AX15-AL15-(AM15/2) -> 31
A16: JKT009 | B16: Chauhan Badal | C16: 12th Mar 2002 | D16: 30th Jan 2025 | E16: =$B$6 -> March | F16: P | G16: P | H16: P | I16: P | J16: P | K16: P | L16: P | M16: P | N16: P | O16: P | P16: P | Q16: P | R16: P | S16: L | T16: P | U16: P | V16: P | W16: P | X16: P | Y16: P | Z16: P | AA16: L | AB16: P | AC16: P | AD16: L | AE16: P | AF16: P | AG16: P | AH16: L | AI16: P | AJ16: P | AK16: =COUNTIF(F16:AJ16,"P") -> 27 | AL16: =COUNTIF(F16:AJ16,"L") -> 4 | AM16: =COUNTIF(F16:AJ16,"HD") -> 0 | AN16: =COUNTIF(F16:AJ16,"NH") -> 0 | AO16: =COUNTIF(F16:AJ16,"FH") -> 0 | AP16: =COUNTIF(F16:AJ16,"T") -> 0 | AQ16: =COUNTIF(F16:AJ16,"ML") -> 0 | AR16: =COUNTIF(F16:AJ16,"EL") -> 0 | AS16: 1 | AT16: =COUNTIF(F16:AJ16,"SL") -> 0 | AU16: 2 | AV16: =COUNTIF(F16:AJ16,"CL") -> 0 | AW16: 2 | AX16: =AK16+AL16+(AM16+AN16+AO16+AP16+AQ16+AR16+AT16+AV16) -> 31 | AY16: =AX16-AL16-(AM16/2) -> 27
A17: JKT010 | B17: Vikas Kotiyan | C17: 18th Sept 1999 | D17: 17th Mar 2025 | E17: =$B$6 -> March | V17: P | W17: P | X17: P | Y17: P | Z17: P | AA17: P | AB17: P | AC17: P | AD17: P | AE17: P | AF17: P | AG17: P | AH17: P | AI17: P | AJ17: P | AK17: =COUNTIF(F17:AJ17,"P") -> 15 | AL17: =COUNTIF(F17:AJ17,"L") -> 0 | AM17: =COUNTIF(F17:AJ17,"HD") -> 0 | AN17: =COUNTIF(F17:AJ17,"NH") -> 0 | AO17: =COUNTIF(F17:AJ17,"FH") -> 0 | AP17: =COUNTIF(F17:AJ17,"T") -> 0 | AQ17: =COUNTIF(F17:AJ17,"ML") -> 0 | AR17: =COUNTIF(F17:AJ17,"EL") -> 0 | AS17: 1 | AT17: =COUNTIF(F17:AJ17,"SL") -> 0 | AU17: 2 | AV17: =COUNTIF(F17:AJ17,"CL") -> 0 | AW17: 2 | AX17: =AK17+AL17+(AM17+AN17+AO17+AP17+AQ17+AR17+AT17+AV17) -> 15 | AY17: =AX17-AL17-(AM17/2) -> 15
A18: JKT011 | B18: Pratibha Tiwari | C18: 14th Feb 2004 | D18: 17th Apr 2025 | E18: =$B$6 -> March | AK18: =COUNTIF(F18:AJ18,"P") -> 0 | AL18: =COUNTIF(F18:AJ18,"L") -> 0 | AM18: =COUNTIF(F18:AJ18,"HD") -> 0 | AN18: =COUNTIF(F18:AJ18,"NH") -> 0 | AO18: =COUNTIF(F18:AJ18,"FH") -> 0 | AP18: =COUNTIF(F18:AJ18,"T") -> 0 | AQ18: =COUNTIF(F18:AJ18,"ML") -> 0 | AR18: =COUNTIF(F18:AJ18,"EL") -> 0 | AS18: 1 | AT18: =COUNTIF(F18:AJ18,"SL") -> 0 | AU18: 2 | AV18: =COUNTIF(F18:AJ18,"CL") -> 0 | AW18: 2 | AX18: =AK18+AL18+(AM18+AN18+AO18+AP18+AQ18+AR18+AT18+AV18) -> 0 | AY18: =AX18-AL18-(AM18/2) -> 0
AK19: =COUNTIF(F19:AJ19,"P") -> 0 | AL19: =COUNTIF(F19:AJ19,"L") -> 0 | AM19: =COUNTIF(F19:AJ19,"HD") -> 0 | AN19: =COUNTIF(F19:AJ19,"NH") -> 0 | AO19: =COUNTIF(F19:AJ19,"FH") -> 0 | AP19: =COUNTIF(F19:AJ19,"T") -> 0 | AQ19: =COUNTIF(F19:AJ19,"ML") -> 0 | AR19: =COUNTIF(F19:AJ19,"EL") -> 0 | AS19: 1 | AT19: =COUNTIF(F19:AJ19,"SL") -> 0 | AU19: 2 | AV19: =COUNTIF(F19:AJ19,"CL") -> 0 | AW19: 2 | AX19: =AK19+AL19+(AM19+AN19+AO19+AP19+AQ19+AR19+AT19+AV19) -> 0 | AY19: =AX19-AL19-(AM19/2) -> 0
AK20: =COUNTIF(F20:AJ20,"P") -> 0 | AL20: =COUNTIF(F20:AJ20,"L") -> 0 | AM20: =COUNTIF(F20:AJ20,"HD") -> 0 | AN20: =COUNTIF(F20:AJ20,"NH") -> 0 | AO20: =COUNTIF(F20:AJ20,"FH") -> 0 | AP20: =COUNTIF(F20:AJ20,"T") -> 0 | AQ20: =COUNTIF(F20:AJ20,"ML") -> 0 | AR20: =COUNTIF(F20:AJ20,"EL") -> 0 | AS20: 1 | AT20: =COUNTIF(F20:AJ20,"SL") -> 0 | AU20: 2 | AV20: =COUNTIF(F20:AJ20,"CL") -> 0 | AW20: 2 | AX20: =AK20+AL20+(AM20+AN20+AO20+AP20+AQ20+AR20+AT20+AV20) -> 0 | AY20: =AX20-AL20-(AM20/2) -> 0
AK21: =COUNTIF(F21:AJ21,"P") -> 0 | AL21: =COUNTIF(F21:AJ21,"L") -> 0 | AM21: =COUNTIF(F21:AJ21,"HD") -> 0 | AN21: =COUNTIF(F21:AJ21,"NH") -> 0 | AO21: =COUNTIF(F21:AJ21,"FH") -> 0 | AP21: =COUNTIF(F21:AJ21,"T") -> 0 | AQ21: =COUNTIF(F21:AJ21,"ML") -> 0 | AR21: =COUNTIF(F21:AJ21,"EL") -> 0 | AS21: 1 | AT21: =COUNTIF(F21:AJ21,"SL") -> 0 | AU21: 2 | AV21: =COUNTIF(F21:AJ21,"CL") -> 0 | AW21: 2 | AX21: =AK21+AL21+(AM21+AN21+AO21+AP21+AQ21+AR21+AT21+AV21) -> 0 | AY21: =AX21-AL21-(AM21/2) -> 0
AK22: =COUNTIF(F22:AJ22,"P") -> 0 | AL22: =COUNTIF(F22:AJ22,"L") -> 0 | AM22: =COUNTIF(F22:AJ22,"HD") -> 0 | AN22: =COUNTIF(F22:AJ22,"NH") -> 0 | AO22: =COUNTIF(F22:AJ22,"FH") -> 0 | AP22: =COUNTIF(F22:AJ22,"T") -> 0 | AQ22: =COUNTIF(F22:AJ22,"ML") -> 0 | AR22: =COUNTIF(F22:AJ22,"EL") -> 0 | AS22: 1 | AT22: =COUNTIF(F22:AJ22,"SL") -> 0 | AU22: 2 | AV22: =COUNTIF(F22:AJ22,"CL") -> 0 | AW22: 2 | AX22: =AK22+AL22+(AM22+AN22+AO22+AP22+AQ22+AR22+AT22+AV22) -> 0 | AY22: =AX22-AL22-(AM22/2) -> 0
AK23: =COUNTIF(F23:AJ23,"P") -> 0 | AL23: =COUNTIF(F23:AJ23,"L") -> 0 | AM23: =COUNTIF(F23:AJ23,"HD") -> 0 | AN23: =COUNTIF(F23:AJ23,"NH") -> 0 | AO23: =COUNTIF(F23:AJ23,"FH") -> 0 | AP23: =COUNTIF(F23:AJ23,"T") -> 0 | AQ23: =COUNTIF(F23:AJ23,"ML") -> 0 | AR23: =COUNTIF(F23:AJ23,"EL") -> 0 | AS23: 1 | AT23: =COUNTIF(F23:AJ23,"SL") -> 0 | AU23: 2 | AV23: =COUNTIF(F23:AJ23,"CL") -> 0 | AW23: 2 | AX23: =AK23+AL23+(AM23+AN23+AO23+AP23+AQ23+AR23+AT23+AV23) -> 0 | AY23: =AX23-AL23-(AM23/2) -> 0
AK24: =COUNTIF(F24:AJ24,"P") -> 0 | AL24: =COUNTIF(F24:AJ24,"L") -> 0 | AM24: =COUNTIF(F24:AJ24,"HD") -> 0 | AN24: =COUNTIF(F24:AJ24,"NH") -> 0 | AO24: =COUNTIF(F24:AJ24,"FH") -> 0 | AP24: =COUNTIF(F24:AJ24,"T") -> 0 | AQ24: =COUNTIF(F24:AJ24,"ML") -> 0 | AR24: =COUNTIF(F24:AJ24,"EL") -> 0 | AS24: 1 | AT24: =COUNTIF(F24:AJ24,"SL") -> 0 | AU24: 2 | AV24: =COUNTIF(F24:AJ24,"CL") -> 0 | AW24: 2 | AX24: =AK24+AL24+(AM24+AN24+AO24+AP24+AQ24+AR24+AT24+AV24) -> 0 | AY24: =AX24-AL24-(AM24/2) -> 0
AK25: =COUNTIF(F25:AJ25,"P") -> 0 | AL25: =COUNTIF(F25:AJ25,"L") -> 0 | AM25: =COUNTIF(F25:AJ25,"HD") -> 0 | AN25: =COUNTIF(F25:AJ25,"NH") -> 0 | AO25: =COUNTIF(F25:AJ25,"FH") -> 0 | AP25: =COUNTIF(F25:AJ25,"T") -> 0 | AQ25: =COUNTIF(F25:AJ25,"ML") -> 0 | AR25: =COUNTIF(F25:AJ25,"EL") -> 0 | AS25: 1 | AT25: =COUNTIF(F25:AJ25,"SL") -> 0 | AU25: 2 | AV25: =COUNTIF(F25:AJ25,"CL") -> 0 | AW25: 2 | AX25: =AK25+AL25+(AM25+AN25+AO25+AP25+AQ25+AR25+AT25+AV25) -> 0 | AY25: =AX25-AL25-(AM25/2) -> 0
AK26: =COUNTIF(F26:AJ26,"P") -> 0 | AL26: =COUNTIF(F26:AJ26,"L") -> 0 | AM26: =COUNTIF(F26:AJ26,"HD") -> 0 | AN26: =COUNTIF(F26:AJ26,"NH") -> 0 | AO26: =COUNTIF(F26:AJ26,"FH") -> 0 | AP26: =COUNTIF(F26:AJ26,"T") -> 0 | AQ26: =COUNTIF(F26:AJ26,"ML") -> 0 | AR26: =COUNTIF(F26:AJ26,"EL") -> 0 | AS26: 1 | AT26: =COUNTIF(F26:AJ26,"SL") -> 0 | AU26: 2 | AV26: =COUNTIF(F26:AJ26,"CL") -> 0 | AW26: 2 | AX26: =AK26+AL26+(AM26+AN26+AO26+AP26+AQ26+AR26+AT26+AV26) -> 0 | AY26: =AX26-AL26-(AM26/2) -> 0
AK27: =COUNTIF(F27:AJ27,"P") -> 0 | AL27: =COUNTIF(F27:AJ27,"L") -> 0 | AM27: =COUNTIF(F27:AJ27,"HD") -> 0 | AN27: =COUNTIF(F27:AJ27,"NH") -> 0 | AO27: =COUNTIF(F27:AJ27,"FH") -> 0 | AP27: =COUNTIF(F27:AJ27,"T") -> 0 | AQ27: =COUNTIF(F27:AJ27,"ML") -> 0 | AR27: =COUNTIF(F27:AJ27,"EL") -> 0 | AS27: 1 | AT27: =COUNTIF(F27:AJ27,"SL") -> 0 | AU27: 2 | AV27: =COUNTIF(F27:AJ27,"CL") -> 0 | AW27: 2 | AX27: =AK27+AL27+(AM27+AN27+AO27+AP27+AQ27+AR27+AT27+AV27) -> 0 | AY27: =AX27-AL27-(AM27/2) -> 0
AK28: =COUNTIF(F28:AJ28,"P") -> 0 | AL28: =COUNTIF(F28:AJ28,"L") -> 0 | AM28: =COUNTIF(F28:AJ28,"HD") -> 0 | AN28: =COUNTIF(F28:AJ28,"NH") -> 0 | AO28: =COUNTIF(F28:AJ28,"FH") -> 0 | AP28: =COUNTIF(F28:AJ28,"T") -> 0 | AQ28: =COUNTIF(F28:AJ28,"ML") -> 0 | AR28: =COUNTIF(F28:AJ28,"EL") -> 0 | AS28: 1 | AT28: =COUNTIF(F28:AJ28,"SL") -> 0 | AU28: 2 | AV28: =COUNTIF(F28:AJ28,"CL") -> 0 | AW28: 2 | AX28: =AK28+AL28+(AM28+AN28+AO28+AP28+AQ28+AR28+AT28+AV28) -> 0 | AY28: =AX28-AL28-(AM28/2) -> 0
AK29: =COUNTIF(F29:AJ29,"P") -> 0 | AL29: =COUNTIF(F29:AJ29,"L") -> 0 | AM29: =COUNTIF(F29:AJ29,"HD") -> 0 | AN29: =COUNTIF(F29:AJ29,"NH") -> 0 | AO29: =COUNTIF(F29:AJ29,"FH") -> 0 | AP29: =COUNTIF(F29:AJ29,"T") -> 0 | AQ29: =COUNTIF(F29:AJ29,"ML") -> 0 | AR29: =COUNTIF(F29:AJ29,"EL") -> 0 | AS29: 1 | AT29: =COUNTIF(F29:AJ29,"SL") -> 0 | AU29: 2 | AV29: =COUNTIF(F29:AJ29,"CL") -> 0 | AW29: 2 | AX29: =AK29+AL29+(AM29+AN29+AO29+AP29+AQ29+AR29+AT29+AV29) -> 0 | AY29: =AX29-AL29-(AM29/2) -> 0
AK30: =COUNTIF(F30:AJ30,"P") -> 0 | AL30: =COUNTIF(F30:AJ30,"L") -> 0 | AM30: =COUNTIF(F30:AJ30,"HD") -> 0 | AN30: =COUNTIF(F30:AJ30,"NH") -> 0 | AO30: =COUNTIF(F30:AJ30,"FH") -> 0 | AP30: =COUNTIF(F30:AJ30,"T") -> 0 | AQ30: =COUNTIF(F30:AJ30,"ML") -> 0 | AR30: =COUNTIF(F30:AJ30,"EL") -> 0 | AS30: 1 | AT30: =COUNTIF(F30:AJ30,"SL") -> 0 | AU30: 2 | AV30: =COUNTIF(F30:AJ30,"CL") -> 0 | AW30: 2 | AX30: =AK30+AL30+(AM30+AN30+AO30+AP30+AQ30+AR30+AT30+AV30) -> 0 | AY30: =AX30-AL30-(AM30/2) -> 0
... AK62: =COUNTIF(F62:AJ62,"P") -> 0 | AL62: =COUNTIF(F62:AJ62,"L") -> 0 | AM62: =COUNTIF(F62:AJ62,"HD") -> 0 | AN62: =COUNTIF(F62:AJ62,"NH") -> 0 | AO62: =COUNTIF(F62:AJ62,"FH") -> 0 | AP62: =COUNTIF(F62:AJ62,"T") -> 0 | AQ62: =COUNTIF(F62:AJ62,"ML") -> 0 | AR62: =COUNTIF(F62:AJ62,"EL") -> 0 | AS62: 1 | AT62: =COUNTIF(F62:AJ62,"SL") -> 0 | AU62: 2 | AV62: =COUNTIF(F62:AJ62,"CL") -> 0 | AW62: 2 | AX62: =AK62+AL62+(AM62+AN62+AO62+AP62+AQ62+AR62+AT62+AV62) -> 0 | AY62: =AX62-AL62-(AM62/2) -> 0
A64: Daily Attendance | F64: =COUNTIF(F13:F62,"P") -> 3 | G64: =COUNTIF(G13:G62,"P") -> 4 | H64: =COUNTIF(H13:H62,"P") -> 4 | I64: =COUNTIF(I13:I62,"P") -> 4 | J64: =COUNTIF(J13:J62,"P") -> 4 | K64: =COUNTIF(K13:K62,"P") -> 4 | L64: =COUNTIF(L13:L62,"P") -> 4 | M64: =COUNTIF(M13:M62,"P") -> 3 | ... AJ64: =COUNTIF(AJ13:AJ62,"P") -> 5

Sheet April '25
E1: JAIKALKI TECHNOLOGY PVT. LTD.
E2: Employee Attendance Sheet
B3: =HLOOKUP(B6,$E$3:$O$4,2,0) -> 4 | E3: January | F3: February | G3: March | H3: April | I3: May | J3: June | K3: July | L3: August | M3: September | N3: October | O3: Novemeber | P3: December
E4: 1 | F4: 2 | G4: 3 | H4: 4 | I4: 5 | J4: 6 | K4: 7 | L4: 8 | M4: 9 | N4: 10 | O4: 11 | P4: 12
A5: Year | B5: 2025 | C5: D O B | D5: D O J | E5: Date | F5: 1 | G5: 2 | H5: 3 | I5: 4 | J5: 5 | K5: 6 | L5: 7 | M5: 8 | N5: 9 | O5: 10 | P5: 11 | Q5: 12 | R5: 13 | S5: 14 | T5: 15 | U5: 16 | V5: 17 | W5: 18 | X5: 19 | Y5: 20 | Z5: 21 | AA5: 22 | AB5: 23 | AC5: 24 | AD5: 25 | AE5: 26 | AF5: 27 | AG5: 28 | AH5: 29 | AI5: 30 | AJ5: 31 | AK5: Monthly Attendance Summary
A6: Month | B6: April | E6: Type of Day | F6: =IF(F7="Sun","H","W") -> W | G6: =IF(G7="Sun","H","W") -> W | H6: =IF(H7="Sun","H","W") -> W | I6: =IF(I7="Sun","H","W") -> W | J6: =IF(J7="Sun","H","W") -> W | K6: =IF(K7="Sun","H","W") -> H | L6: =IF(L7="Sun","H","W") -> W | M6: =IF(M7="Sun","H","W") -> W | ... AJ6: =IF(AJ7="Sun","H","W") -> W
A7: Emp. ID | B7: Employee Name | E7: Month | F7: =IFERROR(TEXT(DATE($B$5,$B$3,F$5),"ddd"),"") -> Tue | G7: =IFERROR(TEXT(DATE($B$5,$B$3,G$5),"ddd"),"") -> Wed | H7: =IFERROR(TEXT(DATE($B$5,$B$3,H$5),"ddd"),"") -> Thu | I7: =IFERROR(TEXT(DATE($B$5,$B$3,I$5),"ddd"),"") -> Fri | J7: =IFERROR(TEXT(DATE($B$5,$B$3,J$5),"ddd"),"") -> Sat | K7: =IFERROR(TEXT(DATE($B$5,$B$3,K$5),"ddd"),"") -> Sun | L7: =IFERROR(TEXT(DATE($B$5,$B$3,L$5),"ddd"),"") -> Mon | M7: =IFERROR(TEXT(DATE($B$5,$B$3,M$5),"ddd"),"") -> Tue | ... AJ7: =IFERROR(TEXT(DATE($B$5,$B$3,AJ$5),"ddd"),"") -> Thu | AK7: P | AL7: L | AM7: HD | AN7: NH | AO7: FH | AP7: T | AQ7: ML | AR7: EL | AS7: EL AL | AT7: SL | AU7: SL AL | AV7: CL | AW7: CL AL | AX7: Working Days | AY7: Days Payable
A8: JKT001 | B8: Shyamveer Singh | C8: 11th Sept 1991 | D8: 14th Sept 2024 | E8: =$B$6 -> April | F8: P | G8: P | H8: P | I8: P | J8: P | K8: P | L8: P | M8: P | N8: P | O8: P | P8: P | Q8: P | R8: P | S8: P | T8: P | U8: P | V8: P | W8: P | X8: P | Y8: P | Z8: P | AA8: P | AB8: P | AC8: P | AD8: P | AE8: P | AF8: P | AG8: P | AH8: P | AI8: P | AK8: =COUNTIF(F8:AJ8,"P") -> 30 | AL8: =COUNTIF(F8:AJ8,"L") -> 0 | AM8: =COUNTIF(F8:AJ8,"HD") -> 0 | AN8: =COUNTIF(F8:AJ8,"NH") -> 0 | AO8: =COUNTIF(F8:AJ8,"FH") -> 0 | AP8: =COUNTIF(F8:AJ8,"T") -> 0 | AQ8: =COUNTIF(F8:AJ8,"ML") -> 0 | AR8: =COUNTIF(F8:AJ8,"EL") -> 0 | AS8: 1 | AT8: =COUNTIF(O8:AS8,"SL") -> 0 | AU8: 2 | AV8: =COUNTIF(F8:AJ8,"CL") -> 0 | AW8: 2 | AX8: =AK8+AL8+(AM8+AN8+AO8+AP8+AQ8+AR8+AT8+AV8) -> 30 | AY8: =AX8-AL8-(AM8/2) -> 30
A9: JKT002 | B9: Rohitkumar Kannojiya | C9: 10th May 2001 | D9: 14th Sept 2024 | E9: =$B$6 -> April | F9: P | G9: P | H9: P | I9: P | J9: P | K9: P | L9: P | M9: P | N9: P | O9: P | P9: P | Q9: P | R9: P | S9: P | T9: P | U9: P | V9: P | W9: P | X9: P | Y9: P | Z9: P | AA9: P | AB9: P | AC9: P | AD9: P | AE9: P | AF9: P | AG9: P | AH9: P | AI9: P | AK9: =COUNTIF(F9:AJ9,"P") -> 30 | AL9: =COUNTIF(F9:AJ9,"L") -> 0 | AM9: =COUNTIF(F9:AJ9,"HD") -> 0 | AN9: =COUNTIF(F9:AJ9,"NH") -> 0 | AO9: =COUNTIF(F9:AJ9,"FH") -> 0 | AP9: =COUNTIF(F9:AJ9,"T") -> 0 | AQ9: =COUNTIF(F9:AJ9,"ML") -> 0 | AR9: =COUNTIF(F9:AJ9,"EL") -> 0 | AS9: 1 | AT9: =COUNTIF(O9:AS9,"SL") -> 0 | AU9: 2 | AV9: =COUNTIF(F9:AJ9,"CL") -> 0 | AW9: 2 | AX9: =AK9+AL9+(AM9+AN9+AO9+AP9+AQ9+AR9+AT9+AV9) -> 30 | AY9: =AX9-AL9-(AM9/2) -> 30
A10: JKT003 | B10: Krunal Trivedi | C10: 29th May 1987 | D10: 14th Sept 2024 | E10: =$B$6 -> April | F10: P | G10: P | H10: P | I10: P | J10: P | K10: P | L10: P | M10: P | N10: P | O10: P | P10: P | Q10: P | R10: P | S10: P | T10: P | U10: P | V10: P | W10: P | X10: P | Y10: P | Z10: P | AA10: P | AB10: P | AC10: P | AD10: P | AE10: P | AF10: P | AG10: P | AH10: P | AI10: P | AK10: =COUNTIF(F10:AJ10,"P") -> 30 | AL10: =COUNTIF(F10:AJ10,"L") -> 0 | AM10: =COUNTIF(F10:AJ10,"HD") -> 0 | AN10: =COUNTIF(F10:AJ10,"NH") -> 0 | AO10: =COUNTIF(F10:AJ10,"FH") -> 0 | AP10: =COUNTIF(F10:AJ10,"T") -> 0 | AQ10: =COUNTIF(F10:AJ10,"ML") -> 0 | AR10: =COUNTIF(F10:AJ10,"EL") -> 0 | AS10: 1 | AT10: =COUNTIF(O10:AS10,"SL") -> 0 | AU10: 2 | AV10: =COUNTIF(F10:AJ10,"CL") -> 0 | AW10: 2 | AX10: =AK10+AL10+(AM10+AN10+AO10+AP10+AQ10+AR10+AT10+AV10) -> 30 | AY10: =AX10-AL10-(AM10/2) -> 30
A11: JKT004 | B11: Ranjeetkumar Yadav | C11: 27th Mar 1987 | D11: 14th Sept 2024 | E11: =$B$6 -> April | F11: P | G11: P | H11: P | I11: P | J11: P | K11: P | L11: P | M11: P | N11: P | O11: P | P11: P | Q11: P | R11: P | S11: P | T11: P | U11: P | V11: P | W11: P | X11: P | Y11: P | Z11: P | AA11: P | AB11: P | AC11: P | AD11: P | AE11: P | AF11: P | AG11: P | AH11: P | AI11: P | AK11: =COUNTIF(F11:AJ11,"P") -> 30 | AL11: =COUNTIF(F11:AJ11,"L") -> 0 | AM11: =COUNTIF(F11:AJ11,"HD") -> 0 | AN11: =COUNTIF(F11:AJ11,"NH") -> 0 | AO11: =COUNTIF(F11:AJ11,"FH") -> 0 | AP11: =COUNTIF(F11:AJ11,"T") -> 0 | AQ11: =COUNTIF(F11:AJ11,"ML") -> 0 | AR11: =COUNTIF(F11:AJ11,"EL") -> 0 | AS11: 1 | AT11: =COUNTIF(O11:AS11,"SL") -> 0 | AU11: 2 | AV11: =COUNTIF(F11:AJ11,"CL") -> 0 | AW11: 2 | AX11: =AK11+AL11+(AM11+AN11+AO11+AP11+AQ11+AR11+AT11+AV11) -> 30 | AY11: =AX11-AL11-(AM11/2) -> 30
A12: JKT005 | B12: Santosh Vishwakarma | C12: 4th Jul 1998 | D12: 14th Sept 2024 | E12: =$B$6 -> April | F12: P | G12: P | H12: P | I12: P | J12: P | K12: P | L12: P | M12: P | N12: P | O12: P | P12: P | Q12: P | R12: P | S12: P | T12: P | U12: P | V12: P | W12: P | X12: P | Y12: P | Z12: P | AA12: P | AB12: P | AC12: P | AD12: P | AE12: P | AF12: P | AG12: P | AH12: P | AI12: P | AK12: =COUNTIF(F12:AJ12,"P") -> 30 | AL12: =COUNTIF(F12:AJ12,"L") -> 0 | AM12: =COUNTIF(F12:AJ12,"HD") -> 0 | AN12: =COUNTIF(F12:AJ12,"NH") -> 0 | AO12: =COUNTIF(F12:AJ12,"FH") -> 0 | AP12: =COUNTIF(F12:AJ12,"T") -> 0 | AQ12: =COUNTIF(F12:AJ12,"ML") -> 0 | AR12: =COUNTIF(F12:AJ12,"EL") -> 0 | AS12: 1 | AT12: =COUNTIF(O12:AS12,"SL") -> 0 | AU12: 2 | AV12: =COUNTIF(F12:AJ12,"CL") -> 0 | AW12: 2 | AX12: =AK12+AL12+(AM12+AN12+AO12+AP12+AQ12+AR12+AT12+AV12) -> 30 | AY12: =AX12-AL12-(AM12/2) -> 30
A13: JKT006 | B13: Deepak Borana | C13: 23rd June 2000 | D13: 6th Jan 2025 | E13: =$B$6 -> April | F13: P | G13: P | H13: P | I13: P | J13: P | K13: P | L13: P | M13: P | N13: P | O13: P | P13: P | Q13: P | R13: P | S13: L | T13: P | U13: P | V13: P | W13: P | X13: P | Y13: P | Z13: P | AA13: P | AB13: P | AC13: P | AD13: P | AE13: P | AF13: P | AG13: P | AH13: P | AI13: P | AK13: =COUNTIF(F13:AJ13,"P") -> 29 | AL13: =COUNTIF(F13:AJ13,"L") -> 1 | AM13: =COUNTIF(F13:AJ13,"HD") -> 0 | AN13: =COUNTIF(F13:AJ13,"NH") -> 0 | AO13: =COUNTIF(F13:AJ13,"FH") -> 0 | AP13: =COUNTIF(F13:AJ13,"T") -> 0 | AQ13: =COUNTIF(F13:AJ13,"ML") -> 0 | AR13: =COUNTIF(F13:AJ13,"EL") -> 0 | AS13: 1 | AT13: =COUNTIF(F13:AJ13,"SL") -> 0 | AU13: 2 | AV13: =COUNTIF(F13:AJ13,"CL") -> 0 | AW13: 2 | AX13: =AK13+AL13+(AM13+AN13+AO13+AP13+AQ13+AR13+AT13+AV13) -> 30 | AY13: =AX13-AL13-(AM13/2) -> 29
A14: JKT007 | B14: Jincy Mathew | C14: 19th April 1999 | D14: 13th Jan 2025 | E14: =$B$6 -> April | F14: P | G14: P | H14: P | I14: P | J14: L | K14: P | L14: P | M14: P | N14: P | O14: P | P14: L | Q14: L | R14: P | S14: P | T14: P | U14: P | V14: P | W14: L | X14: L | Y14: P | Z14: P | AA14: P | AB14: P | AC14: P | AD14: P | AE14: L | AF14: P | AG14: P | AH14: P | AI14: P | AK14: =COUNTIF(F14:AJ14,"P") -> 24 | AL14: =COUNTIF(F14:AJ14,"L") -> 6 | AM14: =COUNTIF(F14:AJ14,"HD") -> 0 | AN14: =COUNTIF(F14:AJ14,"NH") -> 0 | AO14: =COUNTIF(F14:AJ14,"FH") -> 0 | AP14: =COUNTIF(F14:AJ14,"T") -> 0 | AQ14: =COUNTIF(F14:AJ14,"ML") -> 0 | AR14: =COUNTIF(F14:AJ14,"EL") -> 0 | AS14: 1 | AT14: =COUNTIF(F14:AJ14,"SL") -> 0 | AU14: 2 | AV14: =COUNTIF(F14:AJ14,"CL") -> 0 | AW14: 2 | AX14: =AK14+AL14+(AM14+AN14+AO14+AP14+AQ14+AR14+AT14+AV14) -> 30 | AY14: =AX14-AL14-(AM14/2) -> 24
